Workbook

Sheet 현황대시보드
B1: 간병서비스 현황 대시보드
B3: ■ 신청 현황 (건) | E3: ■ 미수금 현황 (원)
B4: 총 신청건수 | C4: =COUNTA('간병신청대장'!$A$2:$A$99979) -> 280 | E4: 입금확인 금액 | F4: =SUM('보험청구'!$I:$I) -> 407300000
B5: 완료 | C5: =COUNTIF('간병신청대장'!$W:$W,"완료") -> 216 | E5: 미확인 청구건수 | F5: =COUNTIF('보험청구'!$K:$K,"미확인") -> 119
B6: 진행중 | C6: =COUNTIF('간병신청대장'!$W:$W,"진행중") -> 34 | E6: 추정 미수금 (단가 142,000 기본) | F6: =SUM('보험청구'!$L:$L) -> 127281000
B7: 예정 | C7: =COUNTIF('간병신청대장'!$W:$W,"예정") -> 4 | E7: 총 간병비 지급액 | F7: =SUM('간병비지급'!$I:$I) -> 515206917
B8: 취소 | C8: =COUNTIF('간병신청대장'!$W:$W,"*취소*") -> 24
E9: ■ 미청구 현황 (건)
E10: 미청구(완료·무청구) | F10: =COUNTIF('간병신청대장'!$AG:$AG,"미청구(완료*") -> 2
B11: ■ 간병인 배정 | E11: 미청구(청구지연·진행중) | F11: =COUNTIF('간병신청대장'!$AG:$AG,"미청구(청구지연)") -> 1
B12: 총 배정 간병인 | C12: =COUNTA('간병인배정'!$A$2:$A$99999) -> 268 | E12: 미청구(청구시작안됨) | F12: =COUNTIF('간병신청대장'!$AG:$AG,"미청구(청구시작안됨)") -> 0
B13: 간병인 변경 건(2명+) | C13: =COUNTIF('간병신청대장'!$X$2:$X$225,">1") -> 4 | E13: 미청구 합계 | F13: =F10+F11+F12 -> 3
B16: ■ 원수사별 신청 건수
B17: 원수사 | C17: 건수
B18: 현대해상 | C18: =COUNTIF('간병신청대장'!$I:$I,"*현대해상*") -> 255
B19: 현대해상(SCOR) | C19: =COUNTIF('간병신청대장'!$I:$I,"*현대해상(SCOR)*") -> 34
B20: 삼성화재 | C20: =COUNTIF('간병신청대장'!$I:$I,"*삼성화재*") -> 25

Sheet 보험청구
A1: 청구ID | B1: 신청ID | C1: 고객명 | D1: 회차 | E1: 기준일 | F1: 청구일 | G1: 일수 | H1: 단가 | I1: 입금확인금액 | J1: 단가구분 | K1: 입금확인여부 | L1: 추정미수금 | M1: 보상팀확인 | N1: 비고 | P1: 1584000 | Q1: =P1/124000 -> 12.774194 | R1: =P1/129000 -> 12.27907 | S1: =P1/135000 -> 11.733333 | T1: =P1/140000 -> 11.314286 | U1: =P1/144000 -> 11 | V1: =P1/86000 -> 18.418605 | W1: =P1/155000 -> 10.219355 | X1: =P1/169000 -> 9.3727811
A2: Q0001 | B2: C0005 | C2: {=IFERROR(INDEX('간병신청대장'!$B:$B,MATCH($B2,'간병신청대장'!$A:$A,0)),"")} -> 엄정현 | D2: 4월 1차 | E2: 2026.03.13 | F2: 2026.07.15 | G2: 10 | H2: 144000 | J2: 확인 | K2: 미확인 | L2: =IF($K2="미확인",IF($G2="",0,$G2*$H2),0) -> 1440000 | M2: 입금예정 | N2: 8월 25일 곽주호손해사정인 통화-> 입금 못했다고 인정, 확인 후 입금하겠다고 함
A3: Q0002 | B3: C0005 | C3: {=IFERROR(INDEX('간병신청대장'!$B:$B,MATCH($B3,'간병신청대장'!$A:$A,0)),"")} -> 엄정현 | D3: 7월 2차 | E3: 2026.07.20 | F3: 2026.07.15 | G3: 38 | H3: 144000 | J3: 확인 | K3: 미확인 | L3: =IF($K3="미확인",IF($G3="",0,$G3*$H3),0) -> 5472000 | M3: 입금예정 | N3: 8월 25일 곽주호손해사정인 통화-> 입금 못했다고 인정, 확인 후 입금하겠다고 함
A4: Q0003 | B4: C0006 | C4: {=IFERROR(INDEX('간병신청대장'!$B:$B,MATCH($B4,'간병신청대장'!$A:$A,0)),"")} -> 엄정현 | D4: 4월 1차 | E4: 2026.03.13 | F4: 2026.07.15 | G4: 10 | H4: 144000 | J4: 확인 | K4: 미확인 | L4: =IF($K4="미확인",IF($G4="",0,$G4*$H4),0) -> 1440000 | M4: 입금예정 | N4: 8월 25일 곽주호손해사정인 통화-> 입금 못했다고 인정, 확인 후 입금하겠다고 함
A5: Q0004 | B5: C0008 | C5: {=IFERROR(INDEX('간병신청대장'!$B:$B,MATCH($B5,'간병신청대장'!$A:$A,0)),"")} -> 류미선 | D5: 4월 1차 | E5: 2026.04.29 | G5: 1 | H5: 86000 | I5: =G5*H5 -> 86000 | J5: 확인 | K5: 입금확인 | L5: =IF($K5="미확인",IF($G5="",0,$G5*$H5),0) -> 0 | N5: 8월 25일 이선연 손해사정인 통화-> 4월30일 우리은행 계좌 95,000원 입금 확인
A6: Q0005 | B6: C0010 | C6: {=IFERROR(INDEX('간병신청대장'!$B:$B,MATCH($B6,'간병신청대장'!$A:$A,0)),"")} -> 김미영 | D6: 5월 1차 | E6: 2026.03.30 12:00 | F6: 2026.06.18 | G6: 4 | H6: 86000 | I6: =G6*H6 -> 344000 | J6: 확인 | K6: 입금확인 | L6: =IF($K6="미확인",IF($G6="",0,$G6*$H6),0) -> 0
A7: Q0006 | B7: C0011 | C7: {=IFERROR(INDEX('간병신청대장'!$B:$B,MATCH($B7,'간병신청대장'!$A:$A,0)),"")} -> 김미영 | D7: 5월 1차 | E7: 2026.04.02 | F7: 2026.06.18 | G7: 4 | H7: 155000 | I7: =G7*H7 -> 620000 | J7: 확인 | K7: 입금확인 | L7: =IF($K7="미확인",IF($G7="",0,$G7*$H7),0) -> 0
A8: Q0007 | B8: C0012 | C8: {=IFERROR(INDEX('간병신청대장'!$B:$B,MATCH($B8,'간병신청대장'!$A:$A,0)),"")} -> 성정주 | D8: 4월 1차 | E8: 2026.04.10 16:00 | F8: 2026.04.10 | G8: 9 | H8: 135000 | I8: 1215000 | J8: 확인 | K8: 입금확인 | L8: =IF($K8="미확인",IF($G8="",0,$G8*$H8),0) -> 0
A9: Q0008 | B9: C0012 | C9: {=IFERROR(INDEX('간병신청대장'!$B:$B,MATCH($B9,'간병신청대장'!$A:$A,0)),"")} -> 성정주 | D9: 4월 2차 | E9: 2026.04.20 16:00 | F9: 2026.04.22 | G9: 10 | H9: 135000 | I9: 1350000 | J9: 확인 | K9: 입금확인 | L9: =IF($K9="미확인",IF($G9="",0,$G9*$H9),0) -> 0
A10: Q0009 | B10: C0012 | C10: {=IFERROR(INDEX('간병신청대장'!$B:$B,MATCH($B10,'간병신청대장'!$A:$A,0)),"")} -> 성정주 | D10: 4월 3차 | E10: 2026.04.30 16:00 | F10: 2026.04.30 | G10: 10 | H10: 135000 | I10: 1350000 | J10: 확인 | K10: 입금확인 | L10: =IF($K10="미확인",IF($G10="",0,$G10*$H10),0) -> 0
A11: Q0010 | B11: C0012 | C11: {=IFERROR(INDEX('간병신청대장'!$B:$B,MATCH($B11,'간병신청대장'!$A:$A,0)),"")} -> 성정주 | D11: 5월 1차 | E11: 2026.05.10 16:00 | F11: 2026.05.11 | G11: 10 | H11: 135000 | I11: 1350000 | J11: 확인 | K11: 입금확인 | L11: =IF($K11="미확인",IF($G11="",0,$G11*$H11),0) -> 0
A12: Q0011 | B12: C0012 | C12: {=IFERROR(INDEX('간병신청대장'!$B:$B,MATCH($B12,'간병신청대장'!$A:$A,0)),"")} -> 성정주 | D12: 5월 2차 | E12: 2026.05.20 16:00 | F12: 2026.05.20 | G12: 10 | H12: 135000 | I12: 1350000 | J12: 확인 | K12: 입금확인 | L12: =IF($K12="미확인",IF($G12="",0,$G12*$H12),0) -> 0
A13: Q0012 | B13: C0012 | C13: {=IFERROR(INDEX('간병신청대장'!$B:$B,MATCH($B13,'간병신청대장'!$A:$A,0)),"")} -> 성정주 | D13: 5월 3차 | E13: 2026.05.31 16:00 | F13: 2026.05.31 | G13: 11 | H13: 135000 | I13: 1485000 | J13: 확인 | K13: 입금확인 | L13: =IF($K13="미확인",IF($G13="",0,$G13*$H13),0) -> 0
A14: Q0013 | B14: C0012 | C14: {=IFERROR(INDEX('간병신청대장'!$B:$B,MATCH($B14,'간병신청대장'!$A:$A,0)),"")} -> 성정주 | D14: 6월 1차 | E14: 2026.06.10 16:00 | F14: 2026.06.10 | G14: 10 | H14: 135000 | I14: 1350000 | J14: 확인 | K14: 입금확인 | L14: =IF($K14="미확인",IF($G14="",0,$G14*$H14),0) -> 0
A15: Q0014 | B15: C0012 | C15: {=IFERROR(INDEX('간병신청대장'!$B:$B,MATCH($B15,'간병신청대장'!$A:$A,0)),"")} -> 성정주 | D15: 6월 2차 | E15: 2026.06.13 10:00 | F15: 2026.06.15 | G15: 3 | H15: 135000 | I15: 405000 | J15: 확인 | K15: 입금확인 | L15: =IF($K15="미확인",IF($G15="",0,$G15*$H15),0) -> 0
A16: Q0015 | B16: C0013 | C16: {=IFERROR(INDEX('간병신청대장'!$B:$B,MATCH($B16,'간병신청대장'!$A:$A,0)),"")} -> 김순년 | D16: 4월 1차 | E16: 2026.04.04 12:00 | F16: 2026.04.14 | G16: 3 | H16: 129000 | I16: 387000 | J16: 확인 | K16: 입금확인 | L16: =IF($K16="미확인",IF($G16="",0,$G16*$H16),0) -> 0
A17: Q0016 | B17: C0014 | C17: {=IFERROR(INDEX('간병신청대장'!$B:$B,MATCH($B17,'간병신청대장'!$A:$A,0)),"")} -> 차정옥 | D17: 4월 1차 | E17: 2026.04.10 06:40 | F17: 2026.04.10 | G17: 9 | H17: 129000 | I17: 1161000 | J17: 확인 | K17: 입금확인 | L17: =IF($K17="미확인",IF($G17="",0,$G17*$H17),0) -> 0
A18: Q0017 | B18: C0014 | C18: {=IFERROR(INDEX('간병신청대장'!$B:$B,MATCH($B18,'간병신청대장'!$A:$A,0)),"")} -> 차정옥 | D18: 4월 2차 | E18: 2026.04.20 06:40 | F18: 2026.04.22 | G18: 10 | H18: 129000 | I18: 1290000 | J18: 확인 | K18: 입금확인 | L18: =IF($K18="미확인",IF($G18="",0,$G18*$H18),0) -> 0
A19: Q0018 | B19: C0014 | C19: {=IFERROR(INDEX('간병신청대장'!$B:$B,MATCH($B19,'간병신청대장'!$A:$A,0)),"")} -> 차정옥 | D19: 4월 3차 | E19: 2026.04.30 06:40 | F19: 2026.04.30 | G19: 10 | H19: 129000 | I19: 1290000 | J19: 확인 | K19: 입금확인 | L19: =IF($K19="미확인",IF($G19="",0,$G19*$H19),0) -> 0
... A22: Q0021 | B22: C0014 | C22: {=IFERROR(INDEX('간병신청대장'!$B:$B,MATCH($B22,'간병신청대장'!$A:$A,0)),"")} -> 차정옥 | D22: 5월 3차 | E22: 2026.05.31 06:40 | F22: 2026.05.31 | G22: 11 | H22: 129000 | I22: 1419000 | J22: 확인 | K22: 입금확인 | L22: =IF($K22="미확인",IF($G22="",0,$G22*$H22),0) -> 0
A23: Q0022 | B23: C0015 | C23: {=IFERROR(INDEX('간병신청대장'!$B:$B,MATCH($B23,'간병신청대장'!$A:$A,0)),"")} -> 이춘자 | D23: 4월 1차 | E23: 2026.04.10 08:00 | F23: 2026.04.14 | G23: 9 | H23: 142000 | J23: 추정(기본142,000) | K23: 미확인 | L23: =IF($K23="미확인",IF($G23="",0,$G23*$H23),0) -> 1278000 | M23: 입금예정 | N23: 8월 25일 황상하 손해사정인 통화-> 6월 8일 마지막 청구일 확인-> 정리하고 연락주겠다고 함
A24: Q0023 | B24: C0015 | C24: {=IFERROR(INDEX('간병신청대장'!$B:$B,MATCH($B24,'간병신청대장'!$A:$A,0)),"")} -> 이춘자 | D24: 4월 2차 | E24: 2026.04.20 08:00 | F24: 2026.04.22 | G24: 10 | H24: 142000 | J24: 추정(기본142,000) | K24: 미확인 | L24: =IF($K24="미확인",IF($G24="",0,$G24*$H24),0) -> 1420000 | M24: 입금예정 | N24: 8월 25일 황상하 손해사정인 통화-> 6월 8일 마지막 청구일 확인-> 정리하고 연락주겠다고 함
A25: Q0024 | B25: C0015 | C25: {=IFERROR(INDEX('간병신청대장'!$B:$B,MATCH($B25,'간병신청대장'!$A:$A,0)),"")} -> 이춘자 | D25: 4월 3차 | E25: 2026.04.30 08:00 | F25: 2026.04.30 | G25: 10 | H25: 142000 | J25: 추정(기본142,000) | K25: 미확인 | L25: =IF($K25="미확인",IF($G25="",0,$G25*$H25),0) -> 1420000 | M25: 입금예정 | N25: 8월 25일 황상하 손해사정인 통화-> 6월 8일 마지막 청구일 확인-> 정리하고 연락주겠다고 함
A26: Q0025 | B26: C0015 | C26: {=IFERROR(INDEX('간병신청대장'!$B:$B,MATCH($B26,'간병신청대장'!$A:$A,0)),"")} -> 이춘자 | D26: 5월 1차 | E26: 2026.05.10 08:00 | F26: 2026.05.11 | G26: 10 | H26: 142000 | J26: 추정(기본142,000) | K26: 미확인 | L26: =IF($K26="미확인",IF($G26="",0,$G26*$H26),0) -> 1420000 | M26: 입금예정 | N26: 8월 25일 황상하 손해사정인 통화-> 6월 8일 마지막 청구일 확인-> 정리하고 연락주겠다고 함
A27: Q0026 | B27: C0015 | C27: {=IFERROR(INDEX('간병신청대장'!$B:$B,MATCH($B27,'간병신청대장'!$A:$A,0)),"")} -> 이춘자 | D27: 5월 2차 | E27: 2026.05.20 08:00 | F27: 2026.05.20 | G27: 10 | H27: 142000 | J27: 추정(기본142,000) | K27: 미확인 | L27: =IF($K27="미확인",IF($G27="",0,$G27*$H27),0) -> 1420000 | M27: 입금예정 | N27: 8월 25일 황상하 손해사정인 통화-> 6월 8일 마지막 청구일 확인-> 정리하고 연락주겠다고 함
A28: Q0027 | B28: C0015 | C28: {=IFERROR(INDEX('간병신청대장'!$B:$B,MATCH($B28,'간병신청대장'!$A:$A,0)),"")} -> 이춘자 | D28: 5월 3차 | E28: 2026.05.31 08:00 | F28: 2026.05.31 | G28: 11 | H28: 142000 | J28: 추정(기본142,000) | K28: 미확인 | L28: =IF($K28="미확인",IF($G28="",0,$G28*$H28),0) -> 1562000 | M28: 입금예정 | N28: 8월 25일 황상하 손해사정인 통화-> 6월 8일 마지막 청구일 확인-> 정리하고 연락주겠다고 함
A29: Q0028 | B29: C0015 | C29: {=IFERROR(INDEX('간병신청대장'!$B:$B,MATCH($B29,'간병신청대장'!$A:$A,0)),"")} -> 이춘자 | D29: 6월 1차 | E29: 2026.06.08 15:00 | F29: 2026.06.08 | G29: 9 | H29: 142000 | J29: 추정(기본142,000) | K29: 미확인 | L29: =IF($K29="미확인",IF($G29="",0,$G29*$H29),0) -> 1278000 | M29: 입금예정 | N29: 8월31일 황상하 재통화-> 회사 변경(케어닥-> 리본케어)으로 시간 소요됨, 곧 정리해서 입금 할 예정 09.16 재통화 : 금주중으로 처리 예정
A30: Q0029 | B30: C0017 | C30: {=IFERROR(INDEX('간병신청대장'!$B:$B,MATCH($B30,'간병신청대장'!$A:$A,0)),"")} -> 심윤주 | D30: 4월 1차 | E30: 2026.04.10 07:00 | F30: 2026.04.10 | G30: 9 | H30: 124000 | I30: 1116000 | J30: 확인 | K30: 입금확인 | L30: =IF($K30="미확인",IF($G30="",0,$G30*$H30),0) -> 0
A31: Q0030 | B31: C0017 | C31: {=IFERROR(INDEX('간병신청대장'!$B:$B,MATCH($B31,'간병신청대장'!$A:$A,0)),"")} -> 심윤주 | D31: 4월 2차 | E31: 2026.04.20 07:00 | F31: 2026.04.22 | G31: 10 | H31: 124000 | I31: 1240000 | J31: 확인 | K31: 입금확인 | L31: =IF($K31="미확인",IF($G31="",0,$G31*$H31),0) -> 0
A32: Q0031 | B32: C0017 | C32: {=IFERROR(INDEX('간병신청대장'!$B:$B,MATCH($B32,'간병신청대장'!$A:$A,0)),"")} -> 심윤주 | D32: 4월 3차 | E32: 2026.04.30 07:00 | F32: 2026.04.30 | G32: 10 | H32: 124000 | I32: 1240000 | J32: 확인 | K32: 입금확인 | L32: =IF($K32="미확인",IF($G32="",0,$G32*$H32),0) -> 0
A33: Q0032 | B33: C0017 | C33: {=IFERROR(INDEX('간병신청대장'!$B:$B,MATCH($B33,'간병신청대장'!$A:$A,0)),"")} -> 심윤주 | D33: 5월 1차 | E33: 2026.05.10 07:00 | F33: 2026.05.11 | G33: 10 | H33: 124000 | I33: 1240000 | J33: 확인 | K33: 입금확인 | L33: =IF($K33="미확인",IF($G33="",0,$G33*$H33),0) -> 0
A34: Q0033 | B34: C0017 | C34: {=IFERROR(INDEX('간병신청대장'!$B:$B,MATCH($B34,'간병신청대장'!$A:$A,0)),"")} -> 심윤주 | D34: 5월 2차 | E34: 2026.05.20 07:00 | F34: 2026.05.20 | G34: 10 | H34: 124000 | I34: 1240000 | J34: 확인 | K34: 입금확인 | L34: =IF($K34="미확인",IF($G34="",0,$G34*$H34),0) -> 0
A35: Q0034 | B35: C0017 | C35: {=IFERROR(INDEX('간병신청대장'!$B:$B,MATCH($B35,'간병신청대장'!$A:$A,0)),"")} -> 심윤주 | D35: 5월 3차 | E35: 2026.05.31 07:00 | F35: 2026.05.31 | G35: 11 | H35: 124000 | I35: 1364000 | J35: 확인 | K35: 입금확인 | L35: =IF($K35="미확인",IF($G35="",0,$G35*$H35),0) -> 0
A36: Q0035 | B36: C0017 | C36: {=IFERROR(INDEX('간병신청대장'!$B:$B,MATCH($B36,'간병신청대장'!$A:$A,0)),"")} -> 심윤주 | D36: 6월 1차 | E36: 2026.06.10 07:00 | F36: 2026.06.10 | G36: 10 | H36: 124000 | I36: 1240000 | J36: 확인 | K36: 입금확인 | L36: =IF($K36="미확인",IF($G36="",0,$G36*$H36),0) -> 0
A37: Q0036 | B37: C0017 | C37: {=IFERROR(INDEX('간병신청대장'!$B:$B,MATCH($B37,'간병신청대장'!$A:$A,0)),"")} -> 심윤주 | D37: 6월 2차 | E37: 2026.06.20 07:00 | F37: 2026.06.20 | G37: 10 | H37: 124000 | I37: 1240000 | J37: 확인 | K37: 입금확인 | L37: =IF($K37="미확인",IF($G37="",0,$G37*$H37),0) -> 0
A38: Q0037 | B38: C0017 | C38: {=IFERROR(INDEX('간병신청대장'!$B:$B,MATCH($B38,'간병신청대장'!$A:$A,0)),"")} -> 심윤주 | D38: 6월 3차 | E38: 2026.06.30 07:00 | F38: 2026.06.30 | G38: 10 | H38: 124000 | I38: 1240000 | J38: 확인 | K38: 입금확인 | L38: =IF($K38="미확인",IF($G38="",0,$G38*$H38),0) -> 0
A39: Q0038 | B39: C0017 | C39: {=IFERROR(INDEX('간병신청대장'!$B:$B,MATCH($B39,'간병신청대장'!$A:$A,0)),"")} -> 심윤주 | D39: 7월 1차 | E39: 2026.07.10 07:00 | F39: 2026.07.10 | G39: 10 | H39: 124000 | J39: 확인 | K39: 미확인 | L39: =IF($K39="미확인",IF($G39="",0,$G39*$H39),0) -> 1240000 | M39: 확인중 | N39: 6월30일 부터 7월 10일 건은 케어닥으로 입금 오늘 처리 완료후 문자 확인하기로함 09.18 : 케어닥에서 아직 미처리 상태, 확인 후 회신
A40: Q0039 | B40: C0017 | C40: {=IFERROR(INDEX('간병신청대장'!$B:$B,MATCH($B40,'간병신청대장'!$A:$A,0)),"")} -> 심윤주 | D40: 7월 2차 | E40: 2026.07.20 07:00 | F40: 2026.07.20 | G40: 10 | H40: 124000 | I40: =G40*H40 -> 1240000 | J40: 확인 | K40: 입금확인 | L40: =IF($K40="미확인",IF($G40="",0,$G40*$H40),0) -> 0 | N40: 8월 25일 김민정 손해사정인 통화-> 확인 후 연락하겠다고 함
A41: Q0040 | B41: C0017 | C41: {=IFERROR(INDEX('간병신청대장'!$B:$B,MATCH($B41,'간병신청대장'!$A:$A,0)),"")} -> 심윤주 | D41: 7월 3차 | E41: 2026.07.31 07:00 | F41: 2026.07.31 | G41: 11 | H41: 124000 | I41: =G41*H41 -> 1364000 | J41: 확인 | K41: 입금확인 | L41: =IF($K41="미확인",IF($G41="",0,$G41*$H41),0) -> 0 | N41: 8월 10일 1360000 입금 14일 우리은행 확인 완료
A42: Q0041 | B42: C0017 | C42: {=IFERROR(INDEX('간병신청대장'!$B:$B,MATCH($B42,'간병신청대장'!$A:$A,0)),"")} -> 심윤주 | D42: 8월 1차 | E42: 2026.08.10 07:00 | F42: 2026.08.10 | G42: 10 | H42: 124000 | I42: =G42*H42 -> 1240000 | J42: 확인 | K42: 입금확인 | L42: =IF($K42="미확인",IF($G42="",0,$G42*$H42),0) -> 0 | N42: 8월 25일 김민정 손해사정인 통화-> 확인 후 연락하겠다고 함
...

Sheet 간병인배정
A1: 배정ID | B1: 신청ID | C1: 고객명 | D1: 간병인명 | E1: 생년월일 | F1: 연락처 | G1: 담당센터 | H1: 센터연락처 | I1: 정산유형 | J1: 일급 | K1: 배정완료일시 | L1: 간병시작일시 | M1: 간병종료일시 | N1: 지급계좌
A2: A0001 | B2: C0006 | C2: {=IFERROR(INDEX('간병신청대장'!$B:$B,MATCH($B2,'간병신청대장'!$A:$A,0)),"")} -> 엄정현 | D2: 황지원 | G2: 영등포 | J2: 80000 | L2: 2026.07.21 | M2: 2026.07.24 | N2: 영등포센터
A3: A0002 | B3: C0010 | C3: {=IFERROR(INDEX('간병신청대장'!$B:$B,MATCH($B3,'간병신청대장'!$A:$A,0)),"")} -> 김미영 | D3: 이영자 | F3: 010-9060-6723 | G3: 영등포 | L3: 2026.03.25 17:30 | M3: 2026.03.30 12:00
A4: A0003 | B4: C0012 | C4: {=IFERROR(INDEX('간병신청대장'!$B:$B,MATCH($B4,'간병신청대장'!$A:$A,0)),"")} -> 성정주 | D4: 이숙자 | F4: 010-8636-5285 | G4: 이솔간병 | H4: 010-3876-5343 | I4: 개인 | J4: 135000 | L4: 2026.04.01.16:00 | M4: 2026.06.13 10:00 | N4: 우리은행 1002-057-219315 LISHUZI
A5: A0004 | B5: C0013 | C5: {=IFERROR(INDEX('간병신청대장'!$B:$B,MATCH($B5,'간병신청대장'!$A:$A,0)),"")} -> 김순년 | D5: 차영옥 | E5: 600307-2695814 | F5: 010-8440-8025 | G5: 영등포 | I5: 개인 | J5: 130000 | L5: 2026.04.01.12:00 | M5: 2026.04.04 12:00
A6: A0005 | B6: C0014 | C6: {=IFERROR(INDEX('간병신청대장'!$B:$B,MATCH($B6,'간병신청대장'!$A:$A,0)),"")} -> 차정옥 | D6: 김혜진 | F6: 010-3579-8090 | G6: 엘리트간병센터 | H6: 010-2355-2419 | I6: 개인 | J6: 130000 | L6: 2026.04.01.06:40 | M6: 2026.05.31 11:00 | N6: 농협은행 501015-52-081548 김혜진
A7: A0006 | B7: C0015 | C7: {=IFERROR(INDEX('간병신청대장'!$B:$B,MATCH($B7,'간병신청대장'!$A:$A,0)),"")} -> 이춘자 | D7: 임영진 | F7: 010-2685-2721 | G7: 행복한돌봄 | H7: 010-6601-8539 | J7: 140000 | L7: 2026.01.23. 08:00 | M7: 2026.06.08 15:00 | N7: 새마을금고 9003-2220-02761 임영진
A8: A0007 | B8: C0017 | C8: {=IFERROR(INDEX('간병신청대장'!$B:$B,MATCH($B8,'간병신청대장'!$A:$A,0)),"")} -> 심윤주 | D8: 안연희 | E8: 581115-2523221 | F8: 010-8645-1345 | G8: 영등포 | I8: 개인 | J8: 130000 | L8: 2026.04.01.07:00 | M8: 2026.08.23.10:00 | N8: 우체국 402362-02-144-686 안연희
A9: A0008 | B9: C0018 | C9: {=IFERROR(INDEX('간병신청대장'!$B:$B,MATCH($B9,'간병신청대장'!$A:$A,0)),"")} -> 김진선 | D9: 최옥녀 | E9: 591222-2769916 | F9: 010-5180-1529 | G9: 영등포 | I9: 개인 | J9: 140000 | L9: 2026.04.01 09:00 | M9: 2026.04.06 12:00
A10: A0009 | B10: C0019 | C10: {=IFERROR(INDEX('간병신청대장'!$B:$B,MATCH($B10,'간병신청대장'!$A:$A,0)),"")} -> 김진선 | D10: 엄순희 | F10: 010-5632-0022 | G10: 미래원간병 | H10: 010-8566-9349 | I10: 센터 | J10: 140000 | L10: 2026.04.06 15:00 | M10: 2026.04.08 15:00 | N10: 카카오뱅크 3333-070958871 (강수자) 협회
A11: A0010 | B11: C0020 | C11: {=IFERROR(INDEX('간병신청대장'!$B:$B,MATCH($B11,'간병신청대장'!$A:$A,0)),"")} | D11: 엄순희 | F11: 010-5632-0022 | G11: 미래원간병 | H11: 010-8566-9349 | L11: 2026.04.08 15:00 | M11: 2026.04.13 12:00
A12: A0011 | B12: C0021 | C12: {=IFERROR(INDEX('간병신청대장'!$B:$B,MATCH($B12,'간병신청대장'!$A:$A,0)),"")} | D12: 엄순희 | F12: 010-5632-0022 | G12: 미래원간병 | H12: 010-8566-9349 | L12: 2026.04.13 12:00 | M12: 2026.04.14 12:00
A13: A0012 | B13: C0022 | C13: {=IFERROR(INDEX('간병신청대장'!$B:$B,MATCH($B13,'간병신청대장'!$A:$A,0)),"")} -> 김진선 | D13: 박기남 | F13: 010-5193-3507 | G13: 미소간병인협회 | J13: 140000 | L13: 2026.04.14 12:00 | M13: 2026.04.20 15:00 | N13: 농협 356 1535 7214 13 한봉순(모) 농협 010-5193-3507 박기남
A14: A0013 | B14: C0023 | C14: {=IFERROR(INDEX('간병신청대장'!$B:$B,MATCH($B14,'간병신청대장'!$A:$A,0)),"")} -> 김진선 | D14: 박기남 | F14: 010-5193-3507 | G14: 미소간병인협회 | J14: 140000 | L14: 2026.04.20 15:00 | M14: 2026.04.24 10:00 | N14: 농협 356 1535 7214 13 한봉순(모) 농협 010-5193-3507 박기남
A15: A0014 | B15: C0024 | C15: {=IFERROR(INDEX('간병신청대장'!$B:$B,MATCH($B15,'간병신청대장'!$A:$A,0)),"")} -> 김진선 | D15: 박기남 | F15: 010-5193-3507 | G15: 미소간병인협회 | J15: 140000 | L15: 2026.04.24 11:00 | M15: 2026.05.06 14:00 | N15: 농협 351 0502 1085 43 박기남
A16: A0015 | B16: C0025 | C16: {=IFERROR(INDEX('간병신청대장'!$B:$B,MATCH($B16,'간병신청대장'!$A:$A,0)),"")} -> 김진선 | D16: 박기남 | F16: 010-5193-3507 | G16: 미소간병인협회 | J16: 140000 | L16: 2026.05.06 14:00 | M16: 2026.05.12 14:00
A17: A0016 | B17: C0026 | C17: {=IFERROR(INDEX('간병신청대장'!$B:$B,MATCH($B17,'간병신청대장'!$A:$A,0)),"")} -> 김진선 | D17: 윤진경 | F17: 010-8294-6155 | G17: 미소간병 대구 | J17: 140000 | L17: 2026.05.12 14:00 | M17: 2026.05.16 14:00 | N17: 농협 김강희 351 0845 1336 53
A18: A0017 | B18: C0027 | C18: {=IFERROR(INDEX('간병신청대장'!$B:$B,MATCH($B18,'간병신청대장'!$A:$A,0)),"")} -> 권영술 | D18: 이혜숙 | F18: 010-5195-1954 | G18: 영등포 | I18: 개인 | J18: 130000 | L18: 2026.03.31.12:00 | M18: 2026.04.10 12:00 | N18: 이혜숙.우리은행.1002.429.595707
A19: A0018 | B19: C0028 | C19: {=IFERROR(INDEX('간병신청대장'!$B:$B,MATCH($B19,'간병신청대장'!$A:$A,0)),"")} -> 김진선 | D19: 박기남 | F19: 010-5193-3507 | G19: 미소간병인협회 | J19: 140000 | L19: 2026.05.16 14:00 | M19: 2026.05.20 14:00 | N19: 농협 351 0502 1085 43 박기남
A20: A0019 | B20: C0029 | C20: {=IFERROR(INDEX('간병신청대장'!$B:$B,MATCH($B20,'간병신청대장'!$A:$A,0)),"")} -> 김진선 | D20: 박기남 | F20: 010-5193-3507 | G20: 미소간병인협회 | J20: 140000 | L20: 2026.05.20 12:00 | M20: 2026.05.26 13:00 | N20: 농협 351 0502 1085 43 박기남
A21: A0020 | B21: C0030 | C21: {=IFERROR(INDEX('간병신청대장'!$B:$B,MATCH($B21,'간병신청대장'!$A:$A,0)),"")} -> 김진선 | D21: 박기남 | F21: 010-5193-3507 | G21: 미소간병 포항 | J21: 140000 | L21: 2026.05.26 13:00 | M21: 2026.06.02 13:00
A22: A0021 | B22: C0031 | C22: {=IFERROR(INDEX('간병신청대장'!$B:$B,MATCH($B22,'간병신청대장'!$A:$A,0)),"")} -> 김진선 | D22: 박기남 | F22: 010-5193-3507 | G22: 미소간병 포항 | J22: 140000 | L22: 2026.06.02 13:00 | M22: 2026.06.16 17:00 | N22: 농협 351 0502 1085 43 박기남
A23: A0022 | B23: C0032 | C23: {=IFERROR(INDEX('간병신청대장'!$B:$B,MATCH($B23,'간병신청대장'!$A:$A,0)),"")} -> 김진선 | D23: 박지우 | F23: 010-9675-3923 | G23: 미소간병 대구 | J23: 140000 | L23: 2026.06.16 17:00 | M23: 2026.06.19 17:00 | N23: 농협 김강희 351 0845 1336 53
A24: A0023 | B24: C0033 | C24: {=IFERROR(INDEX('간병신청대장'!$B:$B,MATCH($B24,'간병신청대장'!$A:$A,0)),"")} -> 김진선 | D24: 박기남 | F24: 010-5193-3507 | G24: 미소간병 포항 | J24: 140000 | L24: 2026.06.20 10:00 | M24: 2026.07.14 12:00 | N24: 농협 351 0502 1085 43 박기남
A25: A0024 | B25: C0034 | C25: {=IFERROR(INDEX('간병신청대장'!$B:$B,MATCH($B25,'간병신청대장'!$A:$A,0)),"")} -> 김진선 | D25: 박기남 | F25: 010-5193-3507 | G25: 미소간병 포항 | J25: 140000 | L25: 2026.07.14 12:00 | M25: 2026.07.28 12:00 | N25: 농협 351 0502 1085 43 박기남
A26: A0025 | B26: C0035 | C26: {=IFERROR(INDEX('간병신청대장'!$B:$B,MATCH($B26,'간병신청대장'!$A:$A,0)),"")} -> 김진선 | D26: 박기남 | F26: 010-5193-3507 | G26: 미소간병 포항 | J26: 140000 | L26: 2026.07.28 12:00 | M26: 2026.08.03 12:00 | N26: 농협 356 1535 7214 13 한봉순(모) 농협 010-5193-3507 박기남
A27: A0026 | B27: C0036 | C27: {=IFERROR(INDEX('간병신청대장'!$B:$B,MATCH($B27,'간병신청대장'!$A:$A,0)),"")} -> 김진선 | D27: 김경한 | F27: 010-6901-7085 | G27: 미소간병 포항 | J27: 140000 | L27: 2026.08.03 12:00 | M27: 2026.08.06 13:00 | N27: 기업은행 1510-7551-2010-11 김경한
A28: A0027 | B28: C0037 | C28: {=IFERROR(INDEX('간병신청대장'!$B:$B,MATCH($B28,'간병신청대장'!$A:$A,0)),"")} -> 권영술 | D28: 유순복 | E28: 660406-6760299 | F28: 010-8332-7116 | G28: 영등포 | J28: 140000 | L28: 2026.04.10 17:00 | M28: 2026.05.11 11:00 | N28: 농협 356 0545 9289 63 YU SHUNFU
A29: A0028 | B29: C0038 | C29: {=IFERROR(INDEX('간병신청대장'!$B:$B,MATCH($B29,'간병신청대장'!$A:$A,0)),"")} -> 전남영 | D29: 서은진 | E29: 510108-2822511 | F29: 010-8689-2929 | G29: 창조 | H29: 010-3568-1059 | I29: 개인 | J29: 130000 | L29: 2026.04.01.12:00 | M29: 2026.05.14 12:00 | N29: 농협302-0566-701181 서은진
A30: A0029 | B30: C0039 | C30: {=IFERROR(INDEX('간병신청대장'!$B:$B,MATCH($B30,'간병신청대장'!$A:$A,0)),"")} -> 전남영 | D30: 정옥화 | F30: 010-5203-8991 | G30: 스마일간병협회 | J30: 135000 | L30: 2026.05.13 12:00 | M30: 2026.06.19:10:00 | N30: 1개월분씩 정산 요청 /카카오뱅크 3333 34 4632 984 (이순련) 협회
A31: A0030 | B31: C0040 | C31: {=IFERROR(INDEX('간병신청대장'!$B:$B,MATCH($B31,'간병신청대장'!$A:$A,0)),"")} -> 전남영 | D31: 송미령 | F31: 010-6310-3030 | G31: 창원진심간병협회 | H31: 010-8551-2418 | J31: 140000 | L31: 2026.06.19 14:00 | M31: 2026.07.27 12:00 | N31: 농협 349-12-144055 김미숙(창원진심)
A32: A0031 | B32: C0041 | C32: {=IFERROR(INDEX('간병신청대장'!$B:$B,MATCH($B32,'간병신청대장'!$A:$A,0)),"")} -> 이성자 | D32: 이영희 | E32: 481219-2403224 | F32: 010-7233-9940 | G32: 영등포 | I32: 개인 | J32: 150000 | L32: 2026.04.01.12:00 | M32: 2026.05.01 11:00 | N32: 농협 483013-52-074105
A33: A0032 | B33: C0042 | C33: {=IFERROR(INDEX('간병신청대장'!$B:$B,MATCH($B33,'간병신청대장'!$A:$A,0)),"")} -> 이성자 | D33: 주예순 | E33: 1956년생 | F33: 010-6879-7789 | G33: 햇살간병 | I33: 개인 | J33: 140000 | L33: 2026.05.06 14:00 | M33: 2026.05.18 13:00 | N33: 농협조명임 356.1196.2339.63
A34: A0033 | B34: C0043 | C34: {=IFERROR(INDEX('간병신청대장'!$B:$B,MATCH($B34,'간병신청대장'!$A:$A,0)),"")} -> 신용찬 | D34: 이옥선 | F34: 010-5751-7299 | G34: 인덕간병센터 | H34: 010-8538-4153 | I34: 개인 | J34: 160000 | L34: 2026.03.31 14:00 | M34: 2026.04.29 12:00 | N34: 신한 110 295 174270 이나경(인덕소장)
A35: A0034 | B35: C0044 | C35: {=IFERROR(INDEX('간병신청대장'!$B:$B,MATCH($B35,'간병신청대장'!$A:$A,0)),"")} -> 오죽삼 | D35: 이경순 | E35: 630828-2222211 | F35: 010-7587-8295 | G35: 영등포 | L35: 2026.04.01.16:00 | M35: 2026.04.01 19:30
A36: A0035 | B36: C0045 | C36: {=IFERROR(INDEX('간병신청대장'!$B:$B,MATCH($B36,'간병신청대장'!$A:$A,0)),"")} -> 오죽삼 | D36: 김향자 | E36: 590105-6101193 | F36: 010-5199-1378 | G36: 영등포 | I36: 개인 | J36: 135000 | L36: 2026.04.02. 15:30 | M36: 2026.04.09 16:00 | N36: 하나 126 910362 00707 Jin XIANZI
A37: A0036 | B37: C0046 | C37: {=IFERROR(INDEX('간병신청대장'!$B:$B,MATCH($B37,'간병신청대장'!$A:$A,0)),"")} -> 박영희 | D37: 양미옥 | F37: 010-2022-8689 | G37: 햇살간병 | H37: 010-5676-2577 | I37: 개인(센터경유) | J37: 130000 | L37: 2026.04.01.12:00 | M37: 2026.04.06 19:00 | N37: 조명임
A38: A0037 | B38: C0047 | C38: {=IFERROR(INDEX('간병신청대장'!$B:$B,MATCH($B38,'간병신청대장'!$A:$A,0)),"")} -> 조하랑 | D38: 최정은 | E38: 630625-2580412 | F38: 010-8458-3971 | G38: 한마음간병협회 | H38: 010-4661-4435 | I38: 개인 | J38: 140000 | L38: 2026.03.23 13:00 | M38: 2026.04.03 12:00
A39: A0038 | B39: C0048 | C39: {=IFERROR(INDEX('간병신청대장'!$B:$B,MATCH($B39,'간병신청대장'!$A:$A,0)),"")} -> 조하륜 | D39: 강은선 | E39: 630526-2630315 | F39: 010-9610-5173 | G39: 한마음간병협회 | H39: 010-4661-4435 | I39: 개인 | J39: 140000 | L39: 2026.03.23 13:00 | M39: 2026.04.03 12:00
A40: A0039 | B40: C0050 | C40: {=IFERROR(INDEX('간병신청대장'!$B:$B,MATCH($B40,'간병신청대장'!$A:$A,0)),"")} -> 전영수 | D40: 김학수 | F40: 010-9988-8526 | G40: 스마일간병협회 | H40: 010-6586-4312 | I40: 협회 | J40: 135000 | L40: 2026.04.01.17:00 | M40: 2026.04.17 12:00 | N40: 카카오뱅크 3333 34 4632 984 (이순련) 협회
...

Sheet 간병신청대장
A1: 신청ID | B1: 고객명 | C1: 성별 | D1: 생년월일 | E1: 연락처 | F1: 시도 | G1: 시군구 | H1: 상세주소 | I1: 원수사 | J1: 증권번호 | K1: 계약일자 | L1: 사고번호 | M1: 손사담당 | N1: 손사연락처 | O1: 손사Fax | P1: 사고발생일 | Q1: 사고유형 | R1: 진단명 | S1: 신청일시 | T1: 시작희망일 | U1: 신청유형 | V1: 예상사용일수 | W1: 현재상태 | X1: 배정간병인수 | Y1: 총지급액 | Z1: 청구건수 | AA1: 미확인청구건수 | AB1: 입금확인금액 | AC1: 추정미수금 | AD1: 간병시작일 | AE1: 마지막청구일 | AF1: 경과일수 | AG1: 청구분류 | AH1: 비고 | AI1: 기준일자→ | AJ1: 46283
A2: C0001 | B2: 김옥경 | C2: 여 | D2: 19661230 | E2: 010-3875-7912 | F2: 울산광역시 | G2: 울주군 | H2: 미근길 133-2 | I2: 현대해상(SCOR) | J2: L02546672401 | K2: 2025.10.23 | L2: 2511201552 | P2: 2025.10.29 | Q2: 질병 | S2: 2025.11.04 | U2: 재택 | V2: 2일 | W2: 완료 | X2: =COUNTIF('간병인배정'!$B:$B,$A2) -> 1 | Y2: =SUMIF('간병비지급'!$B:$B,$A2,'간병비지급'!$I:$I) -> 184000 | Z2: =COUNTIF('보험청구'!$B:$B,$A2) -> 1 | AA2: =COUNTIFS('보험청구'!$B:$B,$A2,'보험청구'!$J:$J,"미확인") -> 0 | AB2: =SUMIF('보험청구'!$B:$B,$A2,'보험청구'!$I:$I) -> 0 | AC2: =SUMIF('보험청구'!$B:$B,$A2,'보험청구'!$L:$L) -> 0 | AF2: =IF($AE2="","",$AJ$1-$AE2) | AG2: =IF(OR($W2="서비스 취소",$W2="서비스취소",$W2="미해당",$W2="예정",$W2=""),"제외",IF(AND($W2="완료",$Z2=0),"미청구(완료·무청구)",IF(AND($W2="진행중",$Z2=0,$AD2<>"",$AJ$1-$AD2>=10),"미청구(청구시작안됨)",IF(AND($W2="진행중",$Z2>0,$AJ$1-$AE2>=10),"미청구(청구지연)","정상")))) -> 정상
A3: C0002 | B3: 박지원 | C3: 여 | D3: 19670204 | E3: 010-2473-2079 | F3: 서울특별시 | G3: 노원구 | H3: 한글비석로 36길 64-5 102호 | I3: 현대해상(SCOR) | J3: L02551003720 | K3: 2025.11.27 | L3: 2512948000 | P3: 2025.12.07 | Q3: 상해 | S3: 2025.12.17 | U3: 재택 | V3: 8일 | W3: 완료 | X3: =COUNTIF('간병인배정'!$B:$B,$A3) -> 1 | Y3: =SUMIF('간병비지급'!$B:$B,$A3,'간병비지급'!$I:$I) -> 640000 | Z3: =COUNTIF('보험청구'!$B:$B,$A3) -> 1 | AA3: =COUNTIFS('보험청구'!$B:$B,$A3,'보험청구'!$J:$J,"미확인") -> 0 | AB3: =SUMIF('보험청구'!$B:$B,$A3,'보험청구'!$I:$I) -> 0 | AC3: =SUMIF('보험청구'!$B:$B,$A3,'보험청구'!$L:$L) -> 0 | AF3: =IF($AE3="","",$AJ$1-$AE3) | AG3: =IF(OR($W3="서비스 취소",$W3="서비스취소",$W3="미해당",$W3="예정",$W3=""),"제외",IF(AND($W3="완료",$Z3=0),"미청구(완료·무청구)",IF(AND($W3="진행중",$Z3=0,$AD3<>"",$AJ$1-$AD3>=10),"미청구(청구시작안됨)",IF(AND($W3="진행중",$Z3>0,$AJ$1-$AE3>=10),"미청구(청구지연)","정상")))) -> 정상 | AH3: 손사담당(솔로몬손해사정) 현장 방문
A4: C0003 | B4: 오채은 | C4: 여 | D4: 19670302 | E4: 010-8731-8863 | F4: 전라남도 | G4: 여수시 | H4: 여서동 주공1차 104동 309호 | I4: 현대해상(SCOR) | P4: 2025.11.09 | Q4: 상해 | S4: 2025.12.26 | U4: 재택 | V4: 1일 | W4: 서비스 취소 | X4: =COUNTIF('간병인배정'!$B:$B,$A4) -> 0 | Y4: =SUMIF('간병비지급'!$B:$B,$A4,'간병비지급'!$I:$I) -> 0 | Z4: =COUNTIF('보험청구'!$B:$B,$A4) -> 0 | AA4: =COUNTIFS('보험청구'!$B:$B,$A4,'보험청구'!$J:$J,"미확인") -> 0 | AB4: =SUMIF('보험청구'!$B:$B,$A4,'보험청구'!$I:$I) -> 0 | AC4: =SUMIF('보험청구'!$B:$B,$A4,'보험청구'!$L:$L) -> 0 | AF4: =IF($AE4="","",$AJ$1-$AE4) | AG4: =IF(OR($W4="서비스 취소",$W4="서비스취소",$W4="미해당",$W4="예정",$W4=""),"제외",IF(AND($W4="완료",$Z4=0),"미청구(완료·무청구)",IF(AND($W4="진행중",$Z4=0,$AD4<>"",$AJ$1-$AD4>=10),"미청구(청구시작안됨)",IF(AND($W4="진행중",$Z4>0,$AJ$1-$AE4>=10),"미청구(청구지연)","정상")))) -> 제외 | AH4: 보험정보 미확인(현대해상)
A5: C0004 | B5: 이성근 | C5: 남 | D5: 19800718 | E5: 010-7187-8718 | F5: 세종특별자치시 | G5: 세종시 | H5: 달빛1로 39 202동 1003호 | I5: 현대해상(SCOR) | J5: L02546188171 | K5: 2025.10.20 | L5: 2601359403 | M5: 국두호 | N5: 02-2181-2707 | P5: 2025.12.18 | Q5: 상해 | S5: 2026.01.06 | U5: 재택 | V5: 17일 | W5: 서비스 취소 | X5: =COUNTIF('간병인배정'!$B:$B,$A5) -> 0 | Y5: =SUMIF('간병비지급'!$B:$B,$A5,'간병비지급'!$I:$I) -> 0 | Z5: =COUNTIF('보험청구'!$B:$B,$A5) -> 0 | AA5: =COUNTIFS('보험청구'!$B:$B,$A5,'보험청구'!$J:$J,"미확인") -> 0 | AB5: =SUMIF('보험청구'!$B:$B,$A5,'보험청구'!$I:$I) -> 0 | AC5: =SUMIF('보험청구'!$B:$B,$A5,'보험청구'!$L:$L) -> 0 | AF5: =IF($AE5="","",$AJ$1-$AE5) | AG5: =IF(OR($W5="서비스 취소",$W5="서비스취소",$W5="미해당",$W5="예정",$W5=""),"제외",IF(AND($W5="완료",$Z5=0),"미청구(완료·무청구)",IF(AND($W5="진행중",$Z5=0,$AD5<>"",$AJ$1-$AD5>=10),"미청구(청구시작안됨)",IF(AND($W5="진행중",$Z5>0,$AJ$1-$AE5>=10),"미청구(청구지연)","정상")))) -> 제외 | AH5: 고객 변심에 의한 취소
A6: C0005 | B6: 엄정현 | C6: 남 | D6: 19751203 | E6: 010-8006-2268 | F6: 강원특별자치도 | G6: 양양군 | H6: 구룡령로 1103-29 | I6: 현대해상(SCOR) | J6: L02525539304 | K6: 2025.10.17 | L6: 2601723805 | M6: 곽주호 | N6: 042-829-1466 | P6: 2026.01.15 | Q6: 상해 | S6: 2026.01.15 | U6: 재택 | V6: 20일 | W6: 완료 | X6: =COUNTIF('간병인배정'!$B:$B,$A6) -> 0 | Y6: =SUMIF('간병비지급'!$B:$B,$A6,'간병비지급'!$I:$I) -> 0 | Z6: =COUNTIF('보험청구'!$B:$B,$A6) -> 2 | AA6: =COUNTIFS('보험청구'!$B:$B,$A6,'보험청구'!$J:$J,"미확인") -> 0 | AB6: =SUMIF('보험청구'!$B:$B,$A6,'보험청구'!$I:$I) -> 0 | AC6: =SUMIF('보험청구'!$B:$B,$A6,'보험청구'!$L:$L) -> 6912000 | AE6: 46223 | AF6: =IF($AE6="","",$AJ$1-$AE6) -> 60 | AG6: =IF(OR($W6="서비스 취소",$W6="서비스취소",$W6="미해당",$W6="예정",$W6=""),"제외",IF(AND($W6="완료",$Z6=0),"미청구(완료·무청구)",IF(AND($W6="진행중",$Z6=0,$AD6<>"",$AJ$1-$AD6>=10),"미청구(청구시작안됨)",IF(AND($W6="진행중",$Z6>0,$AJ$1-$AE6>=10),"미청구(청구지연)","정상")))) -> 정상 | AH6: 고객 사유로 서비스 대기중(02.02부터 예정)
A7: C0006 | B7: 엄정현 | C7: 남 | D7: 19751203 | E7: 010-8006-2268 | F7: 강원특별자치도 | G7: 양양군 | H7: 구룡령로 1103-29 | I7: 현대해상(SCOR) | J7: L02525539304 | K7: 2025.10.17 | L7: 2601723805 | M7: 곽주호 | N7: 042-829-1466 | P7: 2026.01.15 | Q7: 상해 | S7: 2026.01.15 | U7: 재택 | W7: 완료 | X7: =COUNTIF('간병인배정'!$B:$B,$A7) -> 1 | Y7: =SUMIF('간병비지급'!$B:$B,$A7,'간병비지급'!$I:$I) -> 320000 | Z7: =COUNTIF('보험청구'!$B:$B,$A7) -> 1 | AA7: =COUNTIFS('보험청구'!$B:$B,$A7,'보험청구'!$J:$J,"미확인") -> 0 | AB7: =SUMIF('보험청구'!$B:$B,$A7,'보험청구'!$I:$I) -> 0 | AC7: =SUMIF('보험청구'!$B:$B,$A7,'보험청구'!$L:$L) -> 1440000 | AD7: 46224 | AE7: 46094 | AF7: =IF($AE7="","",$AJ$1-$AE7) -> 189 | AG7: =IF(OR($W7="서비스 취소",$W7="서비스취소",$W7="미해당",$W7="예정",$W7=""),"제외",IF(AND($W7="완료",$Z7=0),"미청구(완료·무청구)",IF(AND($W7="진행중",$Z7=0,$AD7<>"",$AJ$1-$AD7>=10),"미청구(청구시작안됨)",IF(AND($W7="진행중",$Z7>0,$AJ$1-$AE7>=10),"미청구(청구지연)","정상")))) -> 정상 | AH7: 고객 사유로 서비스 대기중(02.02부터 예정)
A8: C0007 | B8: 고처자 | C8: 여 | D8: 19490814 | E8: 010-6490-5503 | F8: 전라남도 | G8: 목포시 | H8: 미정 | I8: 현대해상(SCOR) | J8: L02544267102 | K8: 2025.10.01 | L8: 2601965806 | M8: 이상혁 | N8: 02-2181-2717 | P8: 2025.11.29 | Q8: 질병 | S8: 2026.01.19 | U8: 입원 | V8: 30일 | W8: 서비스 취소 | X8: =COUNTIF('간병인배정'!$B:$B,$A8) -> 0 | Y8: =SUMIF('간병비지급'!$B:$B,$A8,'간병비지급'!$I:$I) -> 0 | Z8: =COUNTIF('보험청구'!$B:$B,$A8) -> 0 | AA8: =COUNTIFS('보험청구'!$B:$B,$A8,'보험청구'!$J:$J,"미확인") -> 0 | AB8: =SUMIF('보험청구'!$B:$B,$A8,'보험청구'!$I:$I) -> 0 | AC8: =SUMIF('보험청구'!$B:$B,$A8,'보험청구'!$L:$L) -> 0 | AF8: =IF($AE8="","",$AJ$1-$AE8) | AG8: =IF(OR($W8="서비스 취소",$W8="서비스취소",$W8="미해당",$W8="예정",$W8=""),"제외",IF(AND($W8="완료",$Z8=0),"미청구(완료·무청구)",IF(AND($W8="진행중",$Z8=0,$AD8<>"",$AJ$1-$AD8>=10),"미청구(청구시작안됨)",IF(AND($W8="진행중",$Z8>0,$AJ$1-$AE8>=10),"미청구(청구지연)","정상")))) -> 제외 | AH8: 단가 문제로 매칭 실패
A9: C0008 | B9: 류미선 | C9: 여 | D9: 19730906 | E9: 010-8805-5669 | F9: 대전광역시 | G9: 중구 | H9: 대증로 594길 51 101동 305호 | I9: 현대해상(SCOR) | J9: L02544617364 | K9: 2025.10.02 | L9: 2601B77640 | M9: 이선연 | N9: 02-2181-2713 | O9: 0507-770-6602 | P9: 2026.01.11 | Q9: 상해 | S9: 2026.01.22 | U9: 재택 | V9: 1일 | W9: 완료 | X9: =COUNTIF('간병인배정'!$B:$B,$A9) -> 0 | Y9: =SUMIF('간병비지급'!$B:$B,$A9,'간병비지급'!$I:$I) -> 0 | Z9: =COUNTIF('보험청구'!$B:$B,$A9) -> 1 | AA9: =COUNTIFS('보험청구'!$B:$B,$A9,'보험청구'!$J:$J,"미확인") -> 0 | AB9: =SUMIF('보험청구'!$B:$B,$A9,'보험청구'!$I:$I) -> 86000 | AC9: =SUMIF('보험청구'!$B:$B,$A9,'보험청구'!$L:$L) -> 0 | AE9: 46141 | AF9: =IF($AE9="","",$AJ$1-$AE9) -> 142 | AG9: =IF(OR($W9="서비스 취소",$W9="서비스취소",$W9="미해당",$W9="예정",$W9=""),"제외",IF(AND($W9="완료",$Z9=0),"미청구(완료·무청구)",IF(AND($W9="진행중",$Z9=0,$AD9<>"",$AJ$1-$AD9>=10),"미청구(청구시작안됨)",IF(AND($W9="진행중",$Z9>0,$AJ$1-$AE9>=10),"미청구(청구지연)","정상")))) -> 정상 | AH9: 2026.04.29 서비스제공내역서 발송
A10: C0009 | B10: 이윤진 | C10: 여 | D10: 19690917 | E10: 010-7380-3605 | F10: 서울특별시 | G10: 금천구 | H10: 시흥대로 76길 10 501호 | I10: 현대해상(SCOR) | J10: L02547523447 | K10: 2025.10.29 | L10: 2601B77874 | M10: 이동석 | N10: 042-829-1415 | P10: 2025.12.02 | Q10: 상해 | S10: 2026.01.22 | U10: 재택 | V10: 30일 | W10: 완료 | X10: =COUNTIF('간병인배정'!$B:$B,$A10) -> 1 | Y10: =SUMIF('간병비지급'!$B:$B,$A10,'간병비지급'!$I:$I) -> 240000 | Z10: =COUNTIF('보험청구'!$B:$B,$A10) -> 1 | AA10: =COUNTIFS('보험청구'!$B:$B,$A10,'보험청구'!$J:$J,"미확인") -> 0 | AB10: =SUMIF('보험청구'!$B:$B,$A10,'보험청구'!$I:$I) -> 0 | AC10: =SUMIF('보험청구'!$B:$B,$A10,'보험청구'!$L:$L) -> 0 | AF10: =IF($AE10="","",$AJ$1-$AE10) | AG10: =IF(OR($W10="서비스 취소",$W10="서비스취소",$W10="미해당",$W10="예정",$W10=""),"제외",IF(AND($W10="완료",$Z10=0),"미청구(완료·무청구)",IF(AND($W10="진행중",$Z10=0,$AD10<>"",$AJ$1-$AD10>=10),"미청구(청구시작안됨)",IF(AND($W10="진행중",$Z10>0,$AJ$1-$AE10>=10),"미청구(청구지연)","정상")))) -> 정상
A11: C0010 | B11: 김미영 | C11: 여 | D11: 19740105 | E11: 010-4590-1016 | F11: 경기도 | G11: 강남구 | H11: 강남세브란스병원 | I11: 현대해상(SCOR) | J11: L02550315334 | K11: 2025.11.14 | L11: 2603869925 | M11: 조다혜 | N11: 02-2181-2711 | P11: 2026.03.25 | Q11: 질병 | S11: 2026.03.20 | U11: 입원 | V11: 3일 | W11: 완료 | X11: =COUNTIF('간병인배정'!$B:$B,$A11) -> 1 | Y11: =SUMIF('간병비지급'!$B:$B,$A11,'간병비지급'!$I:$I) -> 0 | Z11: =COUNTIF('보험청구'!$B:$B,$A11) -> 1 | AA11: =COUNTIFS('보험청구'!$B:$B,$A11,'보험청구'!$J:$J,"미확인") -> 0 | AB11: =SUMIF('보험청구'!$B:$B,$A11,'보험청구'!$I:$I) -> 344000 | AC11: =SUMIF('보험청구'!$B:$B,$A11,'보험청구'!$L:$L) -> 0 | AD11: 46106 | AE11: 46111 | AF11: =IF($AE11="","",$AJ$1-$AE11) -> 172 | AG11: =IF(OR($W11="서비스 취소",$W11="서비스취소",$W11="미해당",$W11="예정",$W11=""),"제외",IF(AND($W11="완료",$Z11=0),"미청구(완료·무청구)",IF(AND($W11="진행중",$Z11=0,$AD11<>"",$AJ$1-$AD11>=10),"미청구(청구시작안됨)",IF(AND($W11="진행중",$Z11>0,$AJ$1-$AE11>=10),"미청구(청구지연)","정상")))) -> 정상 | AH11: 퇴원 후 재택까지 연결 필요
A12: C0011 | B12: 김미영 | C12: 여 | D12: 19740105 | E12: 010-4590-1016 | F12: 경기도 | G12: 성남시 | H12: 중원구 은행동 1705 청호빌라 301호 | I12: 현대해상(SCOR) | J12: L02550315334 | K12: 2025.11.14 | L12: 2603869925 | M12: 조다혜 | N12: 02-2181-2711 | P12: 2026.03.25 | Q12: 질병 | S12: 2026.03.20 | U12: 재택 | V12: 3일 | W12: 완료 | X12: =COUNTIF('간병인배정'!$B:$B,$A12) -> 0 | Y12: =SUMIF('간병비지급'!$B:$B,$A12,'간병비지급'!$I:$I) -> 0 | Z12: =COUNTIF('보험청구'!$B:$B,$A12) -> 1 | AA12: =COUNTIFS('보험청구'!$B:$B,$A12,'보험청구'!$J:$J,"미확인") -> 0 | AB12: =SUMIF('보험청구'!$B:$B,$A12,'보험청구'!$I:$I) -> 620000 | AC12: =SUMIF('보험청구'!$B:$B,$A12,'보험청구'!$L:$L) -> 0 | AD12: 46111 | AE12: 46114 | AF12: =IF($AE12="","",$AJ$1-$AE12) -> 169 | AG12: =IF(OR($W12="서비스 취소",$W12="서비스취소",$W12="미해당",$W12="예정",$W12=""),"제외",IF(AND($W12="완료",$Z12=0),"미청구(완료·무청구)",IF(AND($W12="진행중",$Z12=0,$AD12<>"",$AJ$1-$AD12>=10),"미청구(청구시작안됨)",IF(AND($W12="진행중",$Z12>0,$AJ$1-$AE12>=10),"미청구(청구지연)","정상")))) -> 정상
A13: C0012 | B13: 성정주 | D13: 19541118 | E13: 010-9111-7027 | F13: 서울특별시 | G13: 강서구 | H13: 큰나무병원 | I13: 현대해상 | J13: L02214738666 | L13: 2509387828 | M13: 최지혜 인나현 | N13: 051-602-5757 02-2181-2369 | Q13: 질병 | S13: 2025.09.13 | U13: 입원 | V13: 1달 | W13: 완료 | X13: =COUNTIF('간병인배정'!$B:$B,$A13) -> 1 | Y13: =SUMIF('간병비지급'!$B:$B,$A13,'간병비지급'!$I:$I) -> 9855000 | Z13: =COUNTIF('보험청구'!$B:$B,$A13) -> 8 | AA13: =COUNTIFS('보험청구'!$B:$B,$A13,'보험청구'!$J:$J,"미확인") -> 0 | AB13: =SUMIF('보험청구'!$B:$B,$A13,'보험청구'!$I:$I) -> 9855000 | AC13: =SUMIF('보험청구'!$B:$B,$A13,'보험청구'!$L:$L) -> 0 | AD13: 46113 | AE13: 46186 | AF13: =IF($AE13="","",$AJ$1-$AE13) -> 97 | AG13: =IF(OR($W13="서비스 취소",$W13="서비스취소",$W13="미해당",$W13="예정",$W13=""),"제외",IF(AND($W13="완료",$Z13=0),"미청구(완료·무청구)",IF(AND($W13="진행중",$Z13=0,$AD13<>"",$AJ$1-$AD13>=10),"미청구(청구시작안됨)",IF(AND($W13="진행중",$Z13>0,$AJ$1-$AE13>=10),"미청구(청구지연)","정상")))) -> 정상 | AH13: 2026.06.10 기준 65일 잔여한도 (08.13일 완료일
A14: C0013 | B14: 김순년 | C14: 여 | D14: 19530909 | E14: 010-6474-0035 | F14: 대전광역시 | G14: 중구 | H14: 대전보람요양병원 | I14: 현대해상 | J14: L02209995449 | L14: 2511844861 | M14: 조윤 | N14: 02-2181-2587 | Q14: 질병 | S14: 2025.11.22 | U14: 입원 | V14: 4개월 | W14: 완료 | X14: =COUNTIF('간병인배정'!$B:$B,$A14) -> 1 | Y14: =SUMIF('간병비지급'!$B:$B,$A14,'간병비지급'!$I:$I) -> 390000 | Z14: =COUNTIF('보험청구'!$B:$B,$A14) -> 1 | AA14: =COUNTIFS('보험청구'!$B:$B,$A14,'보험청구'!$J:$J,"미확인") -> 0 | AB14: =SUMIF('보험청구'!$B:$B,$A14,'보험청구'!$I:$I) -> 387000 | AC14: =SUMIF('보험청구'!$B:$B,$A14,'보험청구'!$L:$L) -> 0 | AD14: 46113 | AE14: 46116 | AF14: =IF($AE14="","",$AJ$1-$AE14) -> 167 | AG14: =IF(OR($W14="서비스 취소",$W14="서비스취소",$W14="미해당",$W14="예정",$W14=""),"제외",IF(AND($W14="완료",$Z14=0),"미청구(완료·무청구)",IF(AND($W14="진행중",$Z14=0,$AD14<>"",$AJ$1-$AD14>=10),"미청구(청구시작안됨)",IF(AND($W14="진행중",$Z14>0,$AJ$1-$AE14>=10),"미청구(청구지연)","정상")))) -> 정상 | AH14: 퇴원
A15: C0014 | B15: 차정옥 | C15: 여 | D15: 19490415 | E15: 010-7574-1088 | F15: 전북특별자치도 | G15: 전주시 | H15: 더세움병원 | I15: 현대해상 | J15: L02151679013 | L15: 2511845962 | M15: 임동기 | N15: 042-829-1485 | Q15: 질병 | S15: 2025.12.01 | U15: 입원 | V15: 4개월 | W15: 완료 | X15: =COUNTIF('간병인배정'!$B:$B,$A15) -> 1 | Y15: =SUMIF('간병비지급'!$B:$B,$A15,'간병비지급'!$I:$I) -> 7800000 | Z15: =COUNTIF('보험청구'!$B:$B,$A15) -> 6 | AA15: =COUNTIFS('보험청구'!$B:$B,$A15,'보험청구'!$J:$J,"미확인") -> 0 | AB15: =SUMIF('보험청구'!$B:$B,$A15,'보험청구'!$I:$I) -> 7740000 | AC15: =SUMIF('보험청구'!$B:$B,$A15,'보험청구'!$L:$L) -> 0 | AD15: 46113 | AE15: 46173 | AF15: =IF($AE15="","",$AJ$1-$AE15) -> 110 | AG15: =IF(OR($W15="서비스 취소",$W15="서비스취소",$W15="미해당",$W15="예정",$W15=""),"제외",IF(AND($W15="완료",$Z15=0),"미청구(완료·무청구)",IF(AND($W15="진행중",$Z15=0,$AD15<>"",$AJ$1-$AD15>=10),"미청구(청구시작안됨)",IF(AND($W15="진행중",$Z15>0,$AJ$1-$AE15>=10),"미청구(청구지연)","정상")))) -> 정상
A16: C0015 | B16: 이춘자 | C16: 여 | D16: 19440326 | E16: 010-2755-8701 | F16: 전북특별자치도 | G16: 군산시 | H16: 참사랑요양병원 | I16: 현대해상 | J16: L02236920806 | L16: 2512947460 | M16: 황상하 | N16: 042-829-1490 | Q16: 상해 | S16: 2025.12.09 | U16: 입원 | V16: 장기예상 | W16: 완료 | X16: =COUNTIF('간병인배정'!$B:$B,$A16) -> 1 | Y16: =SUMIF('간병비지급'!$B:$B,$A16,'간병비지급'!$I:$I) -> 9590000 | Z16: =COUNTIF('보험청구'!$B:$B,$A16) -> 7 | AA16: =COUNTIFS('보험청구'!$B:$B,$A16,'보험청구'!$J:$J,"미확인") -> 0 | AB16: =SUMIF('보험청구'!$B:$B,$A16,'보험청구'!$I:$I) -> 0 | AC16: =SUMIF('보험청구'!$B:$B,$A16,'보험청구'!$L:$L) -> 9798000 | AD16: 46045 | AE16: 46181 | AF16: =IF($AE16="","",$AJ$1-$AE16) -> 102 | AG16: =IF(OR($W16="서비스 취소",$W16="서비스취소",$W16="미해당",$W16="예정",$W16=""),"제외",IF(AND($W16="완료",$Z16=0),"미청구(완료·무청구)",IF(AND($W16="진행중",$Z16=0,$AD16<>"",$AJ$1-$AD16>=10),"미청구(청구시작안됨)",IF(AND($W16="진행중",$Z16>0,$AJ$1-$AE16>=10),"미청구(청구지연)","정상")))) -> 정상 | AH16: 기존 진행
A17: C0016 | B17: 이정옥 | C17: 여 | D17: 19630306 | E17: 010-3652-3111 | F17: 경기도 | G17: 화성시 | H17: 화성한방병원 | I17: 현대해상 | J17: L02142718057 | L17: 2602691264 | M17: 목승신 | N17: 02-2181-2508 | Q17: 질병 | S17: 2026.02.13 | U17: 입원 | V17: 미정 | W17: 서비스 취소 | X17: =COUNTIF('간병인배정'!$B:$B,$A17) -> 0 | Y17: =SUMIF('간병비지급'!$B:$B,$A17,'간병비지급'!$I:$I) -> 0 | Z17: =COUNTIF('보험청구'!$B:$B,$A17) -> 0 | AA17: =COUNTIFS('보험청구'!$B:$B,$A17,'보험청구'!$J:$J,"미확인") -> 0 | AB17: =SUMIF('보험청구'!$B:$B,$A17,'보험청구'!$I:$I) -> 0 | AC17: =SUMIF('보험청구'!$B:$B,$A17,'보험청구'!$L:$L) -> 0 | AF17: =IF($AE17="","",$AJ$1-$AE17) | AG17: =IF(OR($W17="서비스 취소",$W17="서비스취소",$W17="미해당",$W17="예정",$W17=""),"제외",IF(AND($W17="완료",$Z17=0),"미청구(완료·무청구)",IF(AND($W17="진행중",$Z17=0,$AD17<>"",$AJ$1-$AD17>=10),"미청구(청구시작안됨)",IF(AND($W17="진행중",$Z17>0,$AJ$1-$AE17>=10),"미청구(청구지연)","정상")))) -> 제외
A18: C0017 | B18: 심윤주 | C18: 여 | D18: 19620928 | E18: 010-4632-2336 | F18: 전북특별자치도 | G18: 익산시 | H18: 엔젤요양병원 | I18: 현대해상 | J18: L02113980640 | L18: 2602874418 | M18: 김경희 | N18: 02-2181-2714 02-2181-2563 | O18: 문나영 | P18: 051-602-5750 | Q18: 질병 | S18: 2026.02.21 | U18: 입원 | V18: 장기예상 | W18: 완료 | X18: =COUNTIF('간병인배정'!$B:$B,$A18) -> 1 | Y18: =SUMIF('간병비지급'!$B:$B,$A18,'간병비지급'!$I:$I) -> 18675000 | Z18: =COUNTIF('보험청구'!$B:$B,$A18) -> 16 | AA18: =COUNTIFS('보험청구'!$B:$B,$A18,'보험청구'!$J:$J,"미확인") -> 0 | AB18: =SUMIF('보험청구'!$B:$B,$A18,'보험청구'!$I:$I) -> 17980000 | AC18: =SUMIF('보험청구'!$B:$B,$A18,'보험청구'!$L:$L) -> 1240000 | AD18: 46113 | AE18: 46244 | AF18: =IF($AE18="","",$AJ$1-$AE18) -> 39 | AG18: =IF(OR($W18="서비스 취소",$W18="서비스취소",$W18="미해당",$W18="예정",$W18=""),"제외",IF(AND($W18="완료",$Z18=0),"미청구(완료·무청구)",IF(AND($W18="진행중",$Z18=0,$AD18<>"",$AJ$1-$AD18>=10),"미청구(청구시작안됨)",IF(AND($W18="진행중",$Z18>0,$AJ$1-$AE18>=10),"미청구(청구지연)","정상")))) -> 정상 | AH18: 2026.06.10 기준 100일 잔여한도 (09.18일 완료일/8월23일 간병끝남 /824일과25일청구완료
A19: C0018 | B19: 김진선 | D19: 19490913 | E19: 010-8203-4022 | F19: 경상북도 | G19: 포함시 | H19: 우리연합병원 | I19: 현대해상 | J19: L02200229540 | L19: 2603142073 | M19: 허지승 | N19: 051-602-5726 | Q19: 상해 | S19: 2026.03.14 | U19: 입원 | V19: 2주 | W19: 완료 | X19: =COUNTIF('간병인배정'!$B:$B,$A19) -> 1 | Y19: =SUMIF('간병비지급'!$B:$B,$A19,'간병비지급'!$I:$I) -> 730000 | Z19: =COUNTIF('보험청구'!$B:$B,$A19) -> 1 | AA19: =COUNTIFS('보험청구'!$B:$B,$A19,'보험청구'!$J:$J,"미확인") -> 0 | AB19: =SUMIF('보험청구'!$B:$B,$A19,'보험청구'!$I:$I) -> 864000 | AC19: =SUMIF('보험청구'!$B:$B,$A19,'보험청구'!$L:$L) -> 0 | AD19: 46113 | AE19: 46118 | AF19: =IF($AE19="","",$AJ$1-$AE19) -> 165 | AG19: =IF(OR($W19="서비스 취소",$W19="서비스취소",$W19="미해당",$W19="예정",$W19=""),"제외",IF(AND($W19="완료",$Z19=0),"미청구(완료·무청구)",IF(AND($W19="진행중",$Z19=0,$AD19<>"",$AJ$1-$AD19>=10),"미청구(청구시작안됨)",IF(AND($W19="진행중",$Z19>0,$AJ$1-$AE19>=10),"미청구(청구지연)","정상")))) -> 정상 | AH19: 신규 채용
A20: C0019 | B20: 김진선 | D20: 19490913 | E20: 010-8203-4022 | F20: 대구광역시 | G20: 남구 | H20: 대구가톨릭병원 | I20: 현대해상 | J20: L02200229540 | L20: 2603142073 | M20: 허지승 | N20: 051-602-5726 | Q20: 상해 | S20: 2026.03.14 | U20: 입원 | V20: 2주 | W20: 완료 | X20: =COUNTIF('간병인배정'!$B:$B,$A20) -> 1 | Y20: =SUMIF('간병비지급'!$B:$B,$A20,'간병비지급'!$I:$I) -> 840000 | Z20: =COUNTIF('보험청구'!$B:$B,$A20) -> 1 | AA20: =COUNTIFS('보험청구'!$B:$B,$A20,'보험청구'!$J:$J,"미확인") -> 0 | AB20: =SUMIF('보험청구'!$B:$B,$A20,'보험청구'!$I:$I) -> 864000 | AC20: =SUMIF('보험청구'!$B:$B,$A20,'보험청구'!$L:$L) -> 0 | AD20: 46118 | AE20: 46124 | AF20: =IF($AE20="","",$AJ$1-$AE20) -> 159 | AG20: =IF(OR($W20="서비스 취소",$W20="서비스취소",$W20="미해당",$W20="예정",$W20=""),"제외",IF(AND($W20="완료",$Z20=0),"미청구(완료·무청구)",IF(AND($W20="진행중",$Z20=0,$AD20<>"",$AJ$1-$AD20>=10),"미청구(청구시작안됨)",IF(AND($W20="진행중",$Z20>0,$AJ$1-$AE20>=10),"미청구(청구지연)","정상")))) -> 정상
A21: C0022 | B21: 김진선 | D21: 19490913 | E21: 010-8203-4022 | F21: 대구광역시 | G21: 남구 | H21: 전인병원 | I21: 현대해상 | J21: L02200229540 | L21: 2603142073 | M21: 허지승 | N21: 051-602-5726 | Q21: 상해 | S21: 2026.03.14 | U21: 입원 | V21: 2주 | W21: 완료 | X21: =COUNTIF('간병인배정'!$B:$B,$A21) -> 1 | Y21: =SUMIF('간병비지급'!$B:$B,$A21,'간병비지급'!$I:$I) -> 1120000 | Z21: =COUNTIF('보험청구'!$B:$B,$A21) -> 2 | AA21: =COUNTIFS('보험청구'!$B:$B,$A21,'보험청구'!$J:$J,"미확인") -> 0 | AB21: =SUMIF('보험청구'!$B:$B,$A21,'보험청구'!$I:$I) -> 1152000 | AC21: =SUMIF('보험청구'!$B:$B,$A21,'보험청구'!$L:$L) -> 0 | AD21: 46126 | AE21: 46162 | AF21: =IF($AE21="","",$AJ$1-$AE21) -> 121 | AG21: =IF(OR($W21="서비스 취소",$W21="서비스취소",$W21="미해당",$W21="예정",$W21=""),"제외",IF(AND($W21="완료",$Z21=0),"미청구(완료·무청구)",IF(AND($W21="진행중",$Z21=0,$AD21<>"",$AJ$1-$AD21>=10),"미청구(청구시작안됨)",IF(AND($W21="진행중",$Z21>0,$AJ$1-$AE21>=10),"미청구(청구지연)","정상")))) -> 정상
A22: C0023 | B22: 김진선 | D22: 19490913 | E22: 010-8203-4022 | F22: 대구광역시 | G22: 남구 | H22: 카톨릭대학교 병원 | I22: 현대해상 | J22: L02200229540 | L22: 2603142073 | M22: 허지승 | N22: 051-602-5726 | Q22: 상해 | S22: 2026.03.14 | U22: 입원 | V22: 2주 | W22: 완료 | X22: =COUNTIF('간병인배정'!$B:$B,$A22) -> 1 | Y22: =SUMIF('간병비지급'!$B:$B,$A22,'간병비지급'!$I:$I) -> 700000 | Z22: =COUNTIF('보험청구'!$B:$B,$A22) -> 1 | AA22: =COUNTIFS('보험청구'!$B:$B,$A22,'보험청구'!$J:$J,"미확인") -> 0 | AB22: =SUMIF('보험청구'!$B:$B,$A22,'보험청구'!$I:$I) -> 576000 | AC22: =SUMIF('보험청구'!$B:$B,$A22,'보험청구'!$L:$L) -> 0 | AD22: 46132 | AE22: 46136 | AF22: =IF($AE22="","",$AJ$1-$AE22) -> 147 | AG22: =IF(OR($W22="서비스 취소",$W22="서비스취소",$W22="미해당",$W22="예정",$W22=""),"제외",IF(AND($W22="완료",$Z22=0),"미청구(완료·무청구)",IF(AND($W22="진행중",$Z22=0,$AD22<>"",$AJ$1-$AD22>=10),"미청구(청구시작안됨)",IF(AND($W22="진행중",$Z22>0,$AJ$1-$AE22>=10),"미청구(청구지연)","정상")))) -> 정상
A23: C0024 | B23: 김진선 | D23: 19490913 | E23: 010-8203-4022 | F23: 대구광역시 | G23: 남구 | H23: 전인병원 | I23: 현대해상 | J23: L02200229540 | L23: 2603142073 | M23: 허지승 | N23: 051-602-5726 | Q23: 상해 | S23: 2026.03.14 | U23: 입원 | V23: 2주 | W23: 완료 | X23: =COUNTIF('간병인배정'!$B:$B,$A23) -> 1 | Y23: =SUMIF('간병비지급'!$B:$B,$A23,'간병비지급'!$I:$I) -> 2100000 | Z23: =COUNTIF('보험청구'!$B:$B,$A23) -> 2 | AA23: =COUNTIFS('보험청구'!$B:$B,$A23,'보험청구'!$J:$J,"미확인") -> 0 | AB23: =SUMIF('보험청구'!$B:$B,$A23,'보험청구'!$I:$I) -> 1728000 | AC23: =SUMIF('보험청구'!$B:$B,$A23,'보험청구'!$L:$L) -> 0 | AD23: 46136 | AE23: 46148 | AF23: =IF($AE23="","",$AJ$1-$AE23) -> 135 | AG23: =IF(OR($W23="서비스 취소",$W23="서비스취소",$W23="미해당",$W23="예정",$W23=""),"제외",IF(AND($W23="완료",$Z23=0),"미청구(완료·무청구)",IF(AND($W23="진행중",$Z23=0,$AD23<>"",$AJ$1-$AD23>=10),"미청구(청구시작안됨)",IF(AND($W23="진행중",$Z23>0,$AJ$1-$AE23>=10),"미청구(청구지연)","정상")))) -> 정상
A24: C0025 | B24: 김진선 | D24: 19490913 | E24: 010-8203-4022 | F24: 대구광역시 | G24: 남구 | H24: 카톨릭대학교 병원 | I24: 현대해상 | J24: L02200229540 | L24: 2603142073 | M24: 허지승 | N24: 051-602-5726 | Q24: 상해 | S24: 2026.03.14 | U24: 입원 | V24: 2주 | W24: 완료 | X24: =COUNTIF('간병인배정'!$B:$B,$A24) -> 1 | Y24: =SUMIF('간병비지급'!$B:$B,$A24,'간병비지급'!$I:$I) -> 280000 | Z24: =COUNTIF('보험청구'!$B:$B,$A24) -> 1 | AA24: =COUNTIFS('보험청구'!$B:$B,$A24,'보험청구'!$J:$J,"미확인") -> 0 | AB24: =SUMIF('보험청구'!$B:$B,$A24,'보험청구'!$I:$I) -> 0 | AC24: =SUMIF('보험청구'!$B:$B,$A24,'보험청구'!$L:$L) -> 0 | AD24: 46148 | AF24: =IF($AE24="","",$AJ$1-$AE24) | AG24: =IF(OR($W24="서비스 취소",$W24="서비스취소",$W24="미해당",$W24="예정",$W24=""),"제외",IF(AND($W24="완료",$Z24=0),"미청구(완료·무청구)",IF(AND($W24="진행중",$Z24=0,$AD24<>"",$AJ$1-$AD24>=10),"미청구(청구시작안됨)",IF(AND($W24="진행중",$Z24>0,$AJ$1-$AE24>=10),"미청구(청구지연)","정상")))) -> 정상
A25: C0026 | B25: 김진선 | D25: 19490913 | E25: 010-8203-4022 | F25: 대구광역시 | G25: 남구 | H25: 전인병원 | I25: 현대해상 | J25: L02200229540 | L25: 2603142073 | M25: 허지승 | N25: 051-602-5726 | Q25: 상해 | S25: 2026.03.14 | U25: 입원 | V25: 2주 | W25: 완료 | X25: =COUNTIF('간병인배정'!$B:$B,$A25) -> 1 | Y25: =SUMIF('간병비지급'!$B:$B,$A25,'간병비지급'!$I:$I) -> 560000 | Z25: =COUNTIF('보험청구'!$B:$B,$A25) -> 1 | AA25: =COUNTIFS('보험청구'!$B:$B,$A25,'보험청구'!$J:$J,"미확인") -> 0 | AB25: =SUMIF('보험청구'!$B:$B,$A25,'보험청구'!$I:$I) -> 0 | AC25: =SUMIF('보험청구'!$B:$B,$A25,'보험청구'!$L:$L) -> 0 | AD25: 46154 | AF25: =IF($AE25="","",$AJ$1-$AE25) | AG25: =IF(OR($W25="서비스 취소",$W25="서비스취소",$W25="미해당",$W25="예정",$W25=""),"제외",IF(AND($W25="완료",$Z25=0),"미청구(완료·무청구)",IF(AND($W25="진행중",$Z25=0,$AD25<>"",$AJ$1-$AD25>=10),"미청구(청구시작안됨)",IF(AND($W25="진행중",$Z25>0,$AJ$1-$AE25>=10),"미청구(청구지연)","정상")))) -> 정상
A26: C0027 | B26: 권영술 | D26: 19590327 | E26: 010-3870-8864 | F26: 충청남도 | G26: 천안시 | H26: 천안단국대학교병원 | I26: 현대해상 | J26: L02200115556 | L26: 2603224746 | M26: 이성규 | N26: 062-602-3957 | Q26: 질병 | S26: 2026.03.13 | U26: 입원 | V26: 장기예상 | W26: 완료 | X26: =COUNTIF('간병인배정'!$B:$B,$A26) -> 1 | Y26: =SUMIF('간병비지급'!$B:$B,$A26,'간병비지급'!$I:$I) -> 1170000 | Z26: =COUNTIF('보험청구'!$B:$B,$A26) -> 1 | AA26: =COUNTIFS('보험청구'!$B:$B,$A26,'보험청구'!$J:$J,"미확인") -> 0 | AB26: =SUMIF('보험청구'!$B:$B,$A26,'보험청구'!$I:$I) -> 1626000 | AC26: =SUMIF('보험청구'!$B:$B,$A26,'보험청구'!$L:$L) -> 0 | AD26: 46112 | AE26: 46122 | AF26: =IF($AE26="","",$AJ$1-$AE26) -> 161 | AG26: =IF(OR($W26="서비스 취소",$W26="서비스취소",$W26="미해당",$W26="예정",$W26=""),"제외",IF(AND($W26="완료",$Z26=0),"미청구(완료·무청구)",IF(AND($W26="진행중",$Z26=0,$AD26<>"",$AJ$1-$AD26>=10),"미청구(청구시작안됨)",IF(AND($W26="진행중",$Z26>0,$AJ$1-$AE26>=10),"미청구(청구지연)","정상")))) -> 정상 | AH26: 신규 채용
A27: C0028 | B27: 김진선 | D27: 19490913 | E27: 010-8203-4022 | F27: 대구광역시 | G27: 남구 | H27: 카톨릭대학교 병원 | I27: 현대해상 | J27: L02200229540 | L27: 2603142073 | M27: 허지승 | N27: 051-602-5726 | Q27: 상해 | S27: 2026.03.14 | U27: 입원 | V27: 2주 | W27: 완료 | X27: =COUNTIF('간병인배정'!$B:$B,$A27) -> 1 | Y27: =SUMIF('간병비지급'!$B:$B,$A27,'간병비지급'!$I:$I) -> 560000 | Z27: =COUNTIF('보험청구'!$B:$B,$A27) -> 1 | AA27: =COUNTIFS('보험청구'!$B:$B,$A27,'보험청구'!$J:$J,"미확인") -> 0 | AB27: =SUMIF('보험청구'!$B:$B,$A27,'보험청구'!$I:$I) -> 0 | AC27: =SUMIF('보험청구'!$B:$B,$A27,'보험청구'!$L:$L) -> 0 | AD27: 46158 | AF27: =IF($AE27="","",$AJ$1-$AE27) | AG27: =IF(OR($W27="서비스 취소",$W27="서비스취소",$W27="미해당",$W27="예정",$W27=""),"제외",IF(AND($W27="완료",$Z27=0),"미청구(완료·무청구)",IF(AND($W27="진행중",$Z27=0,$AD27<>"",$AJ$1-$AD27>=10),"미청구(청구시작안됨)",IF(AND($W27="진행중",$Z27>0,$AJ$1-$AE27>=10),"미청구(청구지연)","정상")))) -> 정상 | AH27: 정상종료건 / 총 지급일/청구일 비교 필요
A28: C0029 | B28: 김진선 | D28: 19490913 | E28: 010-8203-4022 | F28: 대구광역시 | G28: 남구 | H28: 전인병원 | I28: 현대해상 | J28: L02200229540 | L28: 2606033391 | N28: 042-602-7053 | Q28: 질병 | S28: 2026.03.14 | U28: 입원 | W28: 완료 | X28: =COUNTIF('간병인배정'!$B:$B,$A28) -> 1 | Y28: =SUMIF('간병비지급'!$B:$B,$A28,'간병비지급'!$I:$I) -> 2940000 | Z28: =COUNTIF('보험청구'!$B:$B,$A28) -> 2 | AA28: =COUNTIFS('보험청구'!$B:$B,$A28,'보험청구'!$J:$J,"미확인") -> 0 | AB28: =SUMIF('보험청구'!$B:$B,$A28,'보험청구'!$I:$I) -> 2880000 | AC28: =SUMIF('보험청구'!$B:$B,$A28,'보험청구'!$L:$L) -> 0 | AD28: 46162 | AE28: 46168 | AF28: =IF($AE28="","",$AJ$1-$AE28) -> 115 | AG28: =IF(OR($W28="서비스 취소",$W28="서비스취소",$W28="미해당",$W28="예정",$W28=""),"제외",IF(AND($W28="완료",$Z28=0),"미청구(완료·무청구)",IF(AND($W28="진행중",$Z28=0,$AD28<>"",$AJ$1-$AD28>=10),"미청구(청구시작안됨)",IF(AND($W28="진행중",$Z28>0,$AJ$1-$AE28>=10),"미청구(청구지연)","정상")))) -> 정상
A29: C0030 | B29: 김진선 | D29: 19490913 | E29: 010-8203-4022 | F29: 대구광역시 | G29: 남구 | H29: 카톨릭대학교 병원 | I29: 현대해상 | J29: L02200229540 | L29: 2606033391 | N29: 042-602-7053 | Q29: 질병 | S29: 2026.03.14 | U29: 입원 | W29: 완료 | X29: =COUNTIF('간병인배정'!$B:$B,$A29) -> 1 | Y29: =SUMIF('간병비지급'!$B:$B,$A29,'간병비지급'!$I:$I) -> 0 | Z29: =COUNTIF('보험청구'!$B:$B,$A29) -> 2 | AA29: =COUNTIFS('보험청구'!$B:$B,$A29,'보험청구'!$J:$J,"미확인") -> 0 | AB29: =SUMIF('보험청구'!$B:$B,$A29,'보험청구'!$I:$I) -> 1008000 | AC29: =SUMIF('보험청구'!$B:$B,$A29,'보험청구'!$L:$L) -> 0 | AD29: 46168 | AE29: 46175 | AF29: =IF($AE29="","",$AJ$1-$AE29) -> 108 | AG29: =IF(OR($W29="서비스 취소",$W29="서비스취소",$W29="미해당",$W29="예정",$W29=""),"제외",IF(AND($W29="완료",$Z29=0),"미청구(완료·무청구)",IF(AND($W29="진행중",$Z29=0,$AD29<>"",$AJ$1-$AD29>=10),"미청구(청구시작안됨)",IF(AND($W29="진행중",$Z29>0,$AJ$1-$AE29>=10),"미청구(청구지연)","정상")))) -> 정상
A30: C0031 | B30: 김진선 | D30: 19490913 | E30: 010-8203-4022 | F30: 대구광역시 | G30: 남구 | H30: 전인병원 | I30: 현대해상 | J30: L02200229540 | L30: 2606033391 | N30: 042-602-7053 | Q30: 질병 | S30: 2026.03.14 | U30: 입원 | W30: 완료 | X30: =COUNTIF('간병인배정'!$B:$B,$A30) -> 1 | Y30: =SUMIF('간병비지급'!$B:$B,$A30,'간병비지급'!$I:$I) -> 840000 | Z30: =COUNTIF('보험청구'!$B:$B,$A30) -> 2 | AA30: =COUNTIFS('보험청구'!$B:$B,$A30,'보험청구'!$J:$J,"미확인") -> 0 | AB30: =SUMIF('보험청구'!$B:$B,$A30,'보험청구'!$I:$I) -> 2016000 | AC30: =SUMIF('보험청구'!$B:$B,$A30,'보험청구'!$L:$L) -> 0 | AD30: 46175 | AE30: 46188 | AF30: =IF($AE30="","",$AJ$1-$AE30) -> 95 | AG30: =IF(OR($W30="서비스 취소",$W30="서비스취소",$W30="미해당",$W30="예정",$W30=""),"제외",IF(AND($W30="완료",$Z30=0),"미청구(완료·무청구)",IF(AND($W30="진행중",$Z30=0,$AD30<>"",$AJ$1-$AD30>=10),"미청구(청구시작안됨)",IF(AND($W30="진행중",$Z30>0,$AJ$1-$AE30>=10),"미청구(청구지연)","정상")))) -> 정상
A31: C0032 | B31: 김진선 | D31: 19490913 | E31: 010-8203-4022 | F31: 대구광역시 | G31: 남구 | H31: 전인병원 | I31: 현대해상 | J31: L02200229540 | L31: 2606033391 | N31: 042-602-7053 | Q31: 질병 | S31: 2026.03.14 | U31: 입원 | W31: 완료 | X31: =COUNTIF('간병인배정'!$B:$B,$A31) -> 1 | Y31: =SUMIF('간병비지급'!$B:$B,$A31,'간병비지급'!$I:$I) -> 420000 | Z31: =COUNTIF('보험청구'!$B:$B,$A31) -> 1 | AA31: =COUNTIFS('보험청구'!$B:$B,$A31,'보험청구'!$J:$J,"미확인") -> 0 | AB31: =SUMIF('보험청구'!$B:$B,$A31,'보험청구'!$I:$I) -> 576000 | AC31: =SUMIF('보험청구'!$B:$B,$A31,'보험청구'!$L:$L) -> 0 | AD31: 46189 | AE31: 46192 | AF31: =IF($AE31="","",$AJ$1-$AE31) -> 91 | AG31: =IF(OR($W31="서비스 취소",$W31="서비스취소",$W31="미해당",$W31="예정",$W31=""),"제외",IF(AND($W31="완료",$Z31=0),"미청구(완료·무청구)",IF(AND($W31="진행중",$Z31=0,$AD31<>"",$AJ$1-$AD31>=10),"미청구(청구시작안됨)",IF(AND($W31="진행중",$Z31>0,$AJ$1-$AE31>=10),"미청구(청구지연)","정상")))) -> 정상
A32: C0033 | B32: 김진선 | D32: 19490913 | E32: 010-8203-4022 | F32: 대구광역시 | G32: 남구 | H32: 전인병원 | I32: 현대해상 | J32: L02200229540 | L32: 2606033391 | M32: 이규섭 | N32: 042-602-7053 | O32: 0507-770-5744 | Q32: 질병 | S32: 2026.03.14 | U32: 입원 | W32: 완료 | X32: =COUNTIF('간병인배정'!$B:$B,$A32) -> 1 | Y32: =SUMIF('간병비지급'!$B:$B,$A32,'간병비지급'!$I:$I) -> 2800000 | Z32: =COUNTIF('보험청구'!$B:$B,$A32) -> 3 | AA32: =COUNTIFS('보험청구'!$B:$B,$A32,'보험청구'!$J:$J,"미확인") -> 0 | AB32: =SUMIF('보험청구'!$B:$B,$A32,'보험청구'!$I:$I) -> 3456000 | AC32: =SUMIF('보험청구'!$B:$B,$A32,'보험청구'!$L:$L) -> 0 | AD32: 46193 | AE32: 46217 | AF32: =IF($AE32="","",$AJ$1-$AE32) -> 66 | AG32: =IF(OR($W32="서비스 취소",$W32="서비스취소",$W32="미해당",$W32="예정",$W32=""),"제외",IF(AND($W32="완료",$Z32=0),"미청구(완료·무청구)",IF(AND($W32="진행중",$Z32=0,$AD32<>"",$AJ$1-$AD32>=10),"미청구(청구시작안됨)",IF(AND($W32="진행중",$Z32>0,$AJ$1-$AE32>=10),"미청구(청구지연)","정상")))) -> 정상
A33: C0034 | B33: 김진선 | D33: 19490913 | E33: 010-8203-4022 | F33: 대구광역시 | G33: 남구 | H33: 카톨릭대학교 병원 | I33: 현대해상 | J33: L02200229540 | L33: 2606033391 | M33: 이규섭 | N33: 042-602-7053 | O33: 0507-770-5744 | Q33: 질병 | S33: 2026.03.14 | U33: 입원 | W33: 완료 | X33: =COUNTIF('간병인배정'!$B:$B,$A33) -> 1 | Y33: =SUMIF('간병비지급'!$B:$B,$A33,'간병비지급'!$I:$I) -> 1400000 | Z33: =COUNTIF('보험청구'!$B:$B,$A33) -> 2 | AA33: =COUNTIFS('보험청구'!$B:$B,$A33,'보험청구'!$J:$J,"미확인") -> 0 | AB33: =SUMIF('보험청구'!$B:$B,$A33,'보험청구'!$I:$I) -> 2016000 | AC33: =SUMIF('보험청구'!$B:$B,$A33,'보험청구'!$L:$L) -> 0 | AD33: 46217 | AE33: 46231 | AF33: =IF($AE33="","",$AJ$1-$AE33) -> 52 | AG33: =IF(OR($W33="서비스 취소",$W33="서비스취소",$W33="미해당",$W33="예정",$W33=""),"제외",IF(AND($W33="완료",$Z33=0),"미청구(완료·무청구)",IF(AND($W33="진행중",$Z33=0,$AD33<>"",$AJ$1-$AD33>=10),"미청구(청구시작안됨)",IF(AND($W33="진행중",$Z33>0,$AJ$1-$AE33>=10),"미청구(청구지연)","정상")))) -> 정상
A34: C0035 | B34: 김진선 | D34: 19490913 | E34: 010-8203-4022 | F34: 경상북도 | G34: 포항시 | H34: 선린병원 | I34: 현대해상 | J34: L02200229540 | L34: 2606033391 | M34: 이규섭 | N34: 042-602-7053 | O34: 0507-770-5744 | Q34: 질병 | S34: 2026.03.14 | U34: 입원 | W34: 완료 | X34: =COUNTIF('간병인배정'!$B:$B,$A34) -> 1 | Y34: =SUMIF('간병비지급'!$B:$B,$A34,'간병비지급'!$I:$I) -> 1960000 | Z34: =COUNTIF('보험청구'!$B:$B,$A34) -> 1 | AA34: =COUNTIFS('보험청구'!$B:$B,$A34,'보험청구'!$J:$J,"미확인") -> 0 | AB34: =SUMIF('보험청구'!$B:$B,$A34,'보험청구'!$I:$I) -> 864000 | AC34: =SUMIF('보험청구'!$B:$B,$A34,'보험청구'!$L:$L) -> 0 | AD34: 46231 | AE34: 46237 | AF34: =IF($AE34="","",$AJ$1-$AE34) -> 46 | AG34: =IF(OR($W34="서비스 취소",$W34="서비스취소",$W34="미해당",$W34="예정",$W34=""),"제외",IF(AND($W34="완료",$Z34=0),"미청구(완료·무청구)",IF(AND($W34="진행중",$Z34=0,$AD34<>"",$AJ$1-$AD34>=10),"미청구(청구시작안됨)",IF(AND($W34="진행중",$Z34>0,$AJ$1-$AE34>=10),"미청구(청구지연)","정상")))) -> 정상
A35: C0036 | B35: 김진선 | D35: 19490913 | E35: 010-8203-4022 | F35: 경상북도 | G35: 포항시 | H35: 선린병원 | I35: 현대해상 | J35: L02200229540 | L35: 2606033391 | M35: 이규섭 | N35: 042-602-7053 | O35: 0507-770-5744 | Q35: 질병 | S35: 2026.03.14 | U35: 입원 | W35: 완료 | X35: =COUNTIF('간병인배정'!$B:$B,$A35) -> 1 | Y35: =SUMIF('간병비지급'!$B:$B,$A35,'간병비지급'!$I:$I) -> 420000 | Z35: =COUNTIF('보험청구'!$B:$B,$A35) -> 1 | AA35: =COUNTIFS('보험청구'!$B:$B,$A35,'보험청구'!$J:$J,"미확인") -> 0 | AB35: =SUMIF('보험청구'!$B:$B,$A35,'보험청구'!$I:$I) -> 576000 | AC35: =SUMIF('보험청구'!$B:$B,$A35,'보험청구'!$L:$L) -> 0 | AD35: 46237 | AE35: 46240 | AF35: =IF($AE35="","",$AJ$1-$AE35) -> 43 | AG35: =IF(OR($W35="서비스 취소",$W35="서비스취소",$W35="미해당",$W35="예정",$W35=""),"제외",IF(AND($W35="완료",$Z35=0),"미청구(완료·무청구)",IF(AND($W35="진행중",$Z35=0,$AD35<>"",$AJ$1-$AD35>=10),"미청구(청구시작안됨)",IF(AND($W35="진행중",$Z35>0,$AJ$1-$AE35>=10),"미청구(청구지연)","정상")))) -> 정상
A36: C0037 | B36: 권영술 | D36: 19590327 | E36: 010-3870-8864 | F36: 충청남도 | G36: 천안시 | H36: 천안단국대학교병원 | I36: 현대해상 | J36: L02200115556 | L36: 2603224746 | M36: 이성규 | N36: 062-602-3957 | Q36: 질병 | S36: 2026.03.13 | U36: 입원 | V36: 장기예상 | W36: 완료 | X36: =COUNTIF('간병인배정'!$B:$B,$A36) -> 1 | Y36: =SUMIF('간병비지급'!$B:$B,$A36,'간병비지급'!$I:$I) -> 4340000 | Z36: =COUNTIF('보험청구'!$B:$B,$A36) -> 3 | AA36: =COUNTIFS('보험청구'!$B:$B,$A36,'보험청구'!$J:$J,"미확인") -> 0 | AB36: =SUMIF('보험청구'!$B:$B,$A36,'보험청구'!$I:$I) -> 4278000 | AC36: =SUMIF('보험청구'!$B:$B,$A36,'보험청구'!$L:$L) -> 0 | AD36: 46122 | AE36: 46153 | AF36: =IF($AE36="","",$AJ$1-$AE36) -> 130 | AG36: =IF(OR($W36="서비스 취소",$W36="서비스취소",$W36="미해당",$W36="예정",$W36=""),"제외",IF(AND($W36="완료",$Z36=0),"미청구(완료·무청구)",IF(AND($W36="진행중",$Z36=0,$AD36<>"",$AJ$1-$AD36>=10),"미청구(청구시작안됨)",IF(AND($W36="진행중",$Z36>0,$AJ$1-$AE36>=10),"미청구(청구지연)","정상")))) -> 정상
A37: C0038 | B37: 전남영 | C37: 여 | D37: 19650117 | E37: 010-4585-8008 | F37: 경상남도 | G37: 창원시 | H37: 이에이씨병원 | I37: 현대해상 | J37: L02244009635 | L37: 2603370234 | M37: 조채영 | N37: 02-2181-2383 | Q37: 질병 | S37: 2026.03.10 | U37: 입원 | V37: 미정 | W37: 완료 | X37: =COUNTIF('간병인배정'!$B:$B,$A37) -> 1 | Y37: =SUMIF('간병비지급'!$B:$B,$A37,'간병비지급'!$I:$I) -> 5590000 | Z37: =COUNTIF('보험청구'!$B:$B,$A37) -> 5 | AA37: =COUNTIFS('보험청구'!$B:$B,$A37,'보험청구'!$J:$J,"미확인") -> 0 | AB37: =SUMIF('보험청구'!$B:$B,$A37,'보험청구'!$I:$I) -> 5670000 | AC37: =SUMIF('보험청구'!$B:$B,$A37,'보험청구'!$L:$L) -> 0 | AD37: 46113 | AE37: 46152 | AF37: =IF($AE37="","",$AJ$1-$AE37) -> 131 | AG37: =IF(OR($W37="서비스 취소",$W37="서비스취소",$W37="미해당",$W37="예정",$W37=""),"제외",IF(AND($W37="완료",$Z37=0),"미청구(완료·무청구)",IF(AND($W37="진행중",$Z37=0,$AD37<>"",$AJ$1-$AD37>=10),"미청구(청구시작안됨)",IF(AND($W37="진행중",$Z37>0,$AJ$1-$AE37>=10),"미청구(청구지연)","정상")))) -> 정상
A38: C0039 | B38: 전남영 | C38: 여 | D38: 19650117 | E38: 010-4585-8008 | F38: 경상남도 | G38: 창원시 | H38: 이에이씨병원 | I38: 현대해상 | J38: L02244009635 | L38: 2603370234 | M38: 조채영 | N38: 02-2181-2383 | Q38: 질병 | S38: 2026.03.10 | U38: 입원 | V38: 미정 | W38: 완료 | X38: =COUNTIF('간병인배정'!$B:$B,$A38) -> 1 | Y38: =SUMIF('간병비지급'!$B:$B,$A38,'간병비지급'!$I:$I) -> 4995000 | Z38: =COUNTIF('보험청구'!$B:$B,$A38) -> 4 | AA38: =COUNTIFS('보험청구'!$B:$B,$A38,'보험청구'!$J:$J,"미확인") -> 0 | AB38: =SUMIF('보험청구'!$B:$B,$A38,'보험청구'!$I:$I) -> 2430000 | AC38: =SUMIF('보험청구'!$B:$B,$A38,'보험청구'!$L:$L) -> 0 | AD38: 46155 | AE38: 46192 | AF38: =IF($AE38="","",$AJ$1-$AE38) -> 91 | AG38: =IF(OR($W38="서비스 취소",$W38="서비스취소",$W38="미해당",$W38="예정",$W38=""),"제외",IF(AND($W38="완료",$Z38=0),"미청구(완료·무청구)",IF(AND($W38="진행중",$Z38=0,$AD38<>"",$AJ$1-$AD38>=10),"미청구(청구시작안됨)",IF(AND($W38="진행중",$Z38>0,$AJ$1-$AE38>=10),"미청구(청구지연)","정상")))) -> 정상
A39: C0040 | B39: 전남영 | C39: 여 | D39: 19650117 | E39: 010-4585-8008 | F39: 경상남도 | G39: 창원시 | H39: 이에이씨병원 | I39: 현대해상 | J39: L02244009635 | L39: 2603370234 | M39: 조채영 | N39: 02-2181-2383 | Q39: 질병 | S39: 2026.03.10 | U39: 입원 | V39: 미정 | W39: 진행중 | X39: =COUNTIF('간병인배정'!$B:$B,$A39) -> 2 | Y39: =SUMIF('간병비지급'!$B:$B,$A39,'간병비지급'!$I:$I) -> 11340000 | Z39: =COUNTIF('보험청구'!$B:$B,$A39) -> 8 | AA39: =COUNTIFS('보험청구'!$B:$B,$A39,'보험청구'!$J:$J,"미확인") -> 0 | AB39: =SUMIF('보험청구'!$B:$B,$A39,'보험청구'!$I:$I) -> 7020000 | AC39: =SUMIF('보험청구'!$B:$B,$A39,'보험청구'!$L:$L) -> 5335000 | AD39: 46192 | AE39: 46275 | AF39: =IF($AE39="","",$AJ$1-$AE39) -> 8 | AG39: =IF(OR($W39="서비스 취소",$W39="서비스취소",$W39="미해당",$W39="예정",$W39=""),"제외",IF(AND($W39="완료",$Z39=0),"미청구(완료·무청구)",IF(AND($W39="진행중",$Z39=0,$AD39<>"",$AJ$1-$AD39>=10),"미청구(청구시작안됨)",IF(AND($W39="진행중",$Z39>0,$AJ$1-$AE39>=10),"미청구(청구지연)","정상")))) -> 정상 | AH39: 7월27일송미령간병사끝나고/교체7월27일이송자간병사투입8월25일 2틀휴무적용10일건 20일건 청구완료
A40: C0041 | B40: 이성자 | C40: 여 | D40: 19551016 | E40: 010-4652-8858 | F40: 충청남도 | G40: 공주시 | H40: 공주의료원 | I40: 현대해상 | J40: L02243775320 | L40: 2603508567 | M40: 이철희 | N40: 051-602-5706 | Q40: 상해 | S40: 2026.03.11 | U40: 입원 | V40: 1달 | W40: 완료 | X40: =COUNTIF('간병인배정'!$B:$B,$A40) -> 1 | Y40: =SUMIF('간병비지급'!$B:$B,$A40,'간병비지급'!$I:$I) -> 4500000 | Z40: =COUNTIF('보험청구'!$B:$B,$A40) -> 3 | AA40: =COUNTIFS('보험청구'!$B:$B,$A40,'보험청구'!$J:$J,"미확인") -> 0 | AB40: =SUMIF('보험청구'!$B:$B,$A40,'보험청구'!$I:$I) -> 4185000 | AC40: =SUMIF('보험청구'!$B:$B,$A40,'보험청구'!$L:$L) -> 0 | AD40: 46113 | AE40: 46143 | AF40: =IF($AE40="","",$AJ$1-$AE40) -> 140 | AG40: =IF(OR($W40="서비스 취소",$W40="서비스취소",$W40="미해당",$W40="예정",$W40=""),"제외",IF(AND($W40="완료",$Z40=0),"미청구(완료·무청구)",IF(AND($W40="진행중",$Z40=0,$AD40<>"",$AJ$1-$AD40>=10),"미청구(청구시작안됨)",IF(AND($W40="진행중",$Z40>0,$AJ$1-$AE40>=10),"미청구(청구지연)","정상")))) -> 정상
...

Sheet 간병비지급
A1: ㄹ | B1: 신청ID | C1: 고객명 | D1: 간병인명 | E1: 회차 | F1: 기준일시 | G1: 일수 | H1: 일급 | I1: 지급액 | J1: 지급여부 | K1: 비고
A2: P0001 | B2: C0006 | C2: {=IFERROR(INDEX('간병신청대장'!$B:$B,MATCH($B2,'간병신청대장'!$A:$A,0)),"")} -> 엄정현 | D2: 황지원 | E2: 7월 3차 | F2: 2026.07.24 | G2: 4 | H2: 80000 | I2: 320000 | J2: 지급
A3: P0002 | B3: C0012 | C3: {=IFERROR(INDEX('간병신청대장'!$B:$B,MATCH($B3,'간병신청대장'!$A:$A,0)),"")} -> 성정주 | D3: 이숙자 | E3: 4월 1차 | F3: 2026.04.10 16:00 | G3: 9 | H3: 135000 | I3: 1215000 | J3: 지급
A4: P0003 | B4: C0012 | C4: {=IFERROR(INDEX('간병신청대장'!$B:$B,MATCH($B4,'간병신청대장'!$A:$A,0)),"")} -> 성정주 | D4: 이숙자 | E4: 4월 2차 | F4: 2026.04.20 16:00 | G4: 10 | H4: 135000 | I4: 1350000 | J4: 지급
A5: P0004 | B5: C0012 | C5: {=IFERROR(INDEX('간병신청대장'!$B:$B,MATCH($B5,'간병신청대장'!$A:$A,0)),"")} -> 성정주 | D5: 이숙자 | E5: 4월 3차 | F5: 2026.04.30 16:00 | G5: 10 | H5: 135000 | I5: 1350000 | J5: 지급
A6: P0005 | B6: C0012 | C6: {=IFERROR(INDEX('간병신청대장'!$B:$B,MATCH($B6,'간병신청대장'!$A:$A,0)),"")} -> 성정주 | D6: 이숙자 | E6: 5월 1차 | F6: 2026.05.10 16:00 | G6: 10 | H6: 135000 | I6: 1350000 | J6: 지급
A7: P0006 | B7: C0012 | C7: {=IFERROR(INDEX('간병신청대장'!$B:$B,MATCH($B7,'간병신청대장'!$A:$A,0)),"")} -> 성정주 | D7: 이숙자 | E7: 5월 2차 | F7: 2026.05.20 16:00 | G7: 10 | H7: 135000 | I7: 1350000 | J7: 지급
A8: P0007 | B8: C0012 | C8: {=IFERROR(INDEX('간병신청대장'!$B:$B,MATCH($B8,'간병신청대장'!$A:$A,0)),"")} -> 성정주 | D8: 이숙자 | E8: 5월 3차 | F8: 2026.05.31 16:00 | G8: 11 | H8: 135000 | I8: 1485000 | J8: 지급
A9: P0008 | B9: C0012 | C9: {=IFERROR(INDEX('간병신청대장'!$B:$B,MATCH($B9,'간병신청대장'!$A:$A,0)),"")} -> 성정주 | D9: 이숙자 | E9: 6월 1차 | F9: 2026.06.10 16:00 | G9: 10 | H9: 135000 | I9: 1350000 | J9: 지급
A10: P0009 | B10: C0012 | C10: {=IFERROR(INDEX('간병신청대장'!$B:$B,MATCH($B10,'간병신청대장'!$A:$A,0)),"")} -> 성정주 | D10: 이숙자 | E10: 6월 2차 | F10: 2026.06.13 10:00 | G10: 3 | H10: 135000 | I10: 405000 | J10: 지급
A11: P0010 | B11: C0013 | C11: {=IFERROR(INDEX('간병신청대장'!$B:$B,MATCH($B11,'간병신청대장'!$A:$A,0)),"")} -> 김순년 | D11: 차영옥 | E11: 4월 1차 | F11: 2026.04.04 12:00 | G11: 3 | H11: 130000 | I11: 390000 | J11: 지급
A12: P0013 | B12: C0014 | C12: {=IFERROR(INDEX('간병신청대장'!$B:$B,MATCH($B12,'간병신청대장'!$A:$A,0)),"")} -> 차정옥 | D12: 김혜진 | E12: 4월 1차 | F12: 2026.04.10 06:40 | G12: 9 | H12: 130000 | I12: 1170000 | J12: 지급
